Traceback (most recent call last):
  File "/home/hokenz/Desktop/schedulebot/pybot.py", line 1, in <module>
    from telegram import InlineKeyboardButton, InlineKeyboardMarkup, Update
  File "/home/hokenz/.local/lib/python3.10/site-packages/telegram/__init__.py", line 197, in <module>
    from . import _version, constants, error, helpers, request, warnings
  File "/home/hokenz/.local/lib/python3.10/site-packages/telegram/request/__init__.py", line 21, in <module>
    from ._httpxrequest import HTTPXRequest
  File "/home/hokenz/.local/lib/python3.10/site-packages/telegram/request/_httpxrequest.py", line 22, in <module>
    import httpx
  File "/home/hokenz/.local/lib/python3.10/site-packages/httpx/__init__.py", line 48, in <module>
    from ._main import main
  File "/home/hokenz/.local/lib/python3.10/site-packages/httpx/_main.py", line 6, in <module>
    import click
  File "/usr/lib/python3/dist-packages/click/__init__.py", line 7, in <module>
    from .core import Argument as Argument
  File "/usr/lib/python3/dist-packages/click/core.py", line 16, in <module>
    from . import types
  File "/usr/lib/python3/dist-packages/click/types.py", line 8, in <module>
    from ._compat import _get_argv_encoding
  File "<frozen importlib._bootstrap>", line 1027, in _find_and_load
  File "<frozen importlib._bootstrap>", line 1006, in _find_and_load_unlocked
  File "<frozen importlib._bootstrap>", line 688, in _load_unlocked
  File "<frozen importlib._bootstrap_external>", line 879, in exec_module
  File "<frozen importlib._bootstrap_external>", line 975, in get_code
  File "<frozen importlib._bootstrap_external>", line 1074, in get_data
KeyboardInterrupt
Error while getting Updates: httpx.ReadError: 
No error handlers are registered, logging exception.
Traceback (most recent call last):
  File "/home/hokenz/.local/lib/python3.10/site-packages/httpcore/_exceptions.py", line 10, in map_exceptions
    yield
  File "/home/hokenz/.local/lib/python3.10/site-packages/httpcore/_backends/anyio.py", line 34, in read
    return await self._stream.receive(max_bytes=max_bytes)
  File "/home/hokenz/.local/lib/python3.10/site-packages/anyio/streams/tls.py", line 198, in receive
    data = await self._call_sslobject_method(self._ssl_object.read, max_bytes)
  File "/home/hokenz/.local/lib/python3.10/site-packages/anyio/streams/tls.py", line 140, in _call_sslobject_method
    data = await self.transport_stream.receive()
  File "/home/hokenz/.local/lib/python3.10/site-packages/anyio/_backends/_asyncio.py", line 1104, in receive
    raise self._protocol.exception from None
anyio.BrokenResourceError

The above exception was the direct cause of the following exception:

Traceback (most recent call last):
  File "/home/hokenz/.local/lib/python3.10/site-packages/httpx/_transports/default.py", line 66, in map_httpcore_exceptions
    yield
  File "/home/hokenz/.local/lib/python3.10/site-packages/httpx/_transports/default.py", line 366, in handle_async_request
    resp = await self._pool.handle_async_request(req)
  File "/home/hokenz/.local/lib/python3.10/site-packages/httpcore/_async/connection_pool.py", line 268, in handle_async_request
    raise exc
  File "/home/hokenz/.local/lib/python3.10/site-packages/httpcore/_async/connection_pool.py", line 251, in handle_async_request
    response = await connection.handle_async_request(request)
  File "/home/hokenz/.local/lib/python3.10/site-packages/httpcore/_async/connection.py", line 103, in handle_async_request
    return await self._connection.handle_async_request(request)
  File "/home/hokenz/.local/lib/python3.10/site-packages/httpcore/_async/http11.py", line 133, in handle_async_request
    raise exc
  File "/home/hokenz/.local/lib/python3.10/site-packages/httpcore/_async/http11.py", line 111, in handle_async_request
    ) = await self._receive_response_headers(**kwargs)
  File "/home/hokenz/.local/lib/python3.10/site-packages/httpcore/_async/http11.py", line 176, in _receive_response_headers
    event = await self._receive_event(timeout=timeout)
  File "/home/hokenz/.local/lib/python3.10/site-packages/httpcore/_async/http11.py", line 212, in _receive_event
    data = await self._network_stream.read(
  File "/home/hokenz/.local/lib/python3.10/site-packages/httpcore/_backends/anyio.py", line 31, in read
    with map_exceptions(exc_map):
  File "/usr/lib/python3.10/contextlib.py", line 153, in __exit__
    self.gen.throw(typ, value, traceback)
  File "/home/hokenz/.local/lib/python3.10/site-packages/httpcore/_exceptions.py", line 14, in map_exceptions
    raise to_exc(exc) from exc
httpcore.ReadError

The above exception was the direct cause of the following exception:

Traceback (most recent call last):
  File "/home/hokenz/.local/lib/python3.10/site-packages/telegram/request/_httpxrequest.py", line 219, in do_request
    res = await self._client.request(
  File "/home/hokenz/.local/lib/python3.10/site-packages/httpx/_client.py", line 1530, in request
    return await self.send(request, auth=auth, follow_redirects=follow_redirects)
  File "/home/hokenz/.local/lib/python3.10/site-packages/httpx/_client.py", line 1617, in send
    response = await self._send_handling_auth(
  File "/home/hokenz/.local/lib/python3.10/site-packages/httpx/_client.py", line 1645, in _send_handling_auth
    response = await self._send_handling_redirects(
  File "/home/hokenz/.local/lib/python3.10/site-packages/httpx/_client.py", line 1682, in _send_handling_redirects
    response = await self._send_single_request(request)
  File "/home/hokenz/.local/lib/python3.10/site-packages/httpx/_client.py", line 1719, in _send_single_request
    response = await transport.handle_async_request(request)
  File "/home/hokenz/.local/lib/python3.10/site-packages/httpx/_transports/default.py", line 365, in handle_async_request
    with map_httpcore_exceptions():
  File "/usr/lib/python3.10/contextlib.py", line 153, in __exit__
    self.gen.throw(typ, value, traceback)
  File "/home/hokenz/.local/lib/python3.10/site-packages/httpx/_transports/default.py", line 83, in map_httpcore_exceptions
    raise mapped_exc(message) from exc
httpx.ReadError

The above exception was the direct cause of the following exception:

Traceback (most recent call last):
  File "/home/hokenz/.local/lib/python3.10/site-packages/telegram/ext/_updater.py", line 640, in _network_loop_retry
    if not await action_cb():
  File "/home/hokenz/.local/lib/python3.10/site-packages/telegram/ext/_updater.py", line 345, in polling_action_cb
    raise exc
  File "/home/hokenz/.local/lib/python3.10/site-packages/telegram/ext/_updater.py", line 334, in polling_action_cb
    updates = await self.bot.get_updates(
  File "/home/hokenz/.local/lib/python3.10/site-packages/telegram/ext/_extbot.py", line 565, in get_updates
    updates = await super().get_updates(
  File "/home/hokenz/.local/lib/python3.10/site-packages/telegram/_bot.py", line 519, in decorator
    result = await func(self, *args, **kwargs)  # skipcq: PYL-E1102
  File "/home/hokenz/.local/lib/python3.10/site-packages/telegram/_bot.py", line 3562, in get_updates
    await self._post(
  File "/home/hokenz/.local/lib/python3.10/site-packages/telegram/_bot.py", line 607, in _post
    return await self._do_post(
  File "/home/hokenz/.local/lib/python3.10/site-packages/telegram/ext/_extbot.py", line 347, in _do_post
    return await super()._do_post(
  File "/home/hokenz/.local/lib/python3.10/site-packages/telegram/_bot.py", line 635, in _do_post
    return await request.post(
  File "/home/hokenz/.local/lib/python3.10/site-packages/telegram/request/_baserequest.py", line 168, in post
    result = await self._request_wrapper(
  File "/home/hokenz/.local/lib/python3.10/site-packages/telegram/request/_baserequest.py", line 288, in _request_wrapper
    raise exc
  File "/home/hokenz/.local/lib/python3.10/site-packages/telegram/request/_baserequest.py", line 278, in _request_wrapper
    code, payload = await self.do_request(
  File "/home/hokenz/.local/lib/python3.10/site-packages/telegram/request/_httpxrequest.py", line 243, in do_request
    raise NetworkError(f"httpx.{err.__class__.__name__}: {err}") from err
telegram.error.NetworkError: httpx.ReadError: 
Error while getting Updates: httpx.ReadError: 
No error handlers are registered, logging exception.
Traceback (most recent call last):
  File "/home/hokenz/.local/lib/python3.10/site-packages/httpcore/_exceptions.py", line 10, in map_exceptions
    yield
  File "/home/hokenz/.local/lib/python3.10/site-packages/httpcore/_backends/anyio.py", line 34, in read
    return await self._stream.receive(max_bytes=max_bytes)
  File "/home/hokenz/.local/lib/python3.10/site-packages/anyio/streams/tls.py", line 198, in receive
    data = await self._call_sslobject_method(self._ssl_object.read, max_bytes)
  File "/home/hokenz/.local/lib/python3.10/site-packages/anyio/streams/tls.py", line 140, in _call_sslobject_method
    data = await self.transport_stream.receive()
  File "/home/hokenz/.local/lib/python3.10/site-packages/anyio/_backends/_asyncio.py", line 1104, in receive
    raise self._protocol.exception from None
anyio.BrokenResourceError

The above exception was the direct cause of the following exception:

Traceback (most recent call last):
  File "/home/hokenz/.local/lib/python3.10/site-packages/httpx/_transports/default.py", line 66, in map_httpcore_exceptions
    yield
  File "/home/hokenz/.local/lib/python3.10/site-packages/httpx/_transports/default.py", line 366, in handle_async_request
    resp = await self._pool.handle_async_request(req)
  File "/home/hokenz/.local/lib/python3.10/site-packages/httpcore/_async/connection_pool.py", line 268, in handle_async_request
    raise exc
  File "/home/hokenz/.local/lib/python3.10/site-packages/httpcore/_async/connection_pool.py", line 251, in handle_async_request
    response = await connection.handle_async_request(request)
  File "/home/hokenz/.local/lib/python3.10/site-packages/httpcore/_async/connection.py", line 103, in handle_async_request
    return await self._connection.handle_async_request(request)
  File "/home/hokenz/.local/lib/python3.10/site-packages/httpcore/_async/http11.py", line 133, in handle_async_request
    raise exc
  File "/home/hokenz/.local/lib/python3.10/site-packages/httpcore/_async/http11.py", line 111, in handle_async_request
    ) = await self._receive_response_headers(**kwargs)
  File "/home/hokenz/.local/lib/python3.10/site-packages/httpcore/_async/http11.py", line 176, in _receive_response_headers
    event = await self._receive_event(timeout=timeout)
  File "/home/hokenz/.local/lib/python3.10/site-packages/httpcore/_async/http11.py", line 212, in _receive_event
    data = await self._network_stream.read(
  File "/home/hokenz/.local/lib/python3.10/site-packages/httpcore/_backends/anyio.py", line 31, in read
    with map_exceptions(exc_map):
  File "/usr/lib/python3.10/contextlib.py", line 153, in __exit__
    self.gen.throw(typ, value, traceback)
  File "/home/hokenz/.local/lib/python3.10/site-packages/httpcore/_exceptions.py", line 14, in map_exceptions
    raise to_exc(exc) from exc
httpcore.ReadError

The above exception was the direct cause of the following exception:

Traceback (most recent call last):
  File "/home/hokenz/.local/lib/python3.10/site-packages/telegram/request/_httpxrequest.py", line 219, in do_request
    res = await self._client.request(
  File "/home/hokenz/.local/lib/python3.10/site-packages/httpx/_client.py", line 1530, in request
    return await self.send(request, auth=auth, follow_redirects=follow_redirects)
  File "/home/hokenz/.local/lib/python3.10/site-packages/httpx/_client.py", line 1617, in send
    response = await self._send_handling_auth(
  File "/home/hokenz/.local/lib/python3.10/site-packages/httpx/_client.py", line 1645, in _send_handling_auth
    response = await self._send_handling_redirects(
  File "/home/hokenz/.local/lib/python3.10/site-packages/httpx/_client.py", line 1682, in _send_handling_redirects
    response = await self._send_single_request(request)
  File "/home/hokenz/.local/lib/python3.10/site-packages/httpx/_client.py", line 1719, in _send_single_request
    response = await transport.handle_async_request(request)
  File "/home/hokenz/.local/lib/python3.10/site-packages/httpx/_transports/default.py", line 365, in handle_async_request
    with map_httpcore_exceptions():
  File "/usr/lib/python3.10/contextlib.py", line 153, in __exit__
    self.gen.throw(typ, value, traceback)
  File "/home/hokenz/.local/lib/python3.10/site-packages/httpx/_transports/default.py", line 83, in map_httpcore_exceptions
    raise mapped_exc(message) from exc
httpx.ReadError

The above exception was the direct cause of the following exception:

Traceback (most recent call last):
  File "/home/hokenz/.local/lib/python3.10/site-packages/telegram/ext/_updater.py", line 640, in _network_loop_retry
    if not await action_cb():
  File "/home/hokenz/.local/lib/python3.10/site-packages/telegram/ext/_updater.py", line 345, in polling_action_cb
    raise exc
  File "/home/hokenz/.local/lib/python3.10/site-packages/telegram/ext/_updater.py", line 334, in polling_action_cb
    updates = await self.bot.get_updates(
  File "/home/hokenz/.local/lib/python3.10/site-packages/telegram/ext/_extbot.py", line 565, in get_updates
    updates = await super().get_updates(
  File "/home/hokenz/.local/lib/python3.10/site-packages/telegram/_bot.py", line 519, in decorator
    result = await func(self, *args, **kwargs)  # skipcq: PYL-E1102
  File "/home/hokenz/.local/lib/python3.10/site-packages/telegram/_bot.py", line 3562, in get_updates
    await self._post(
  File "/home/hokenz/.local/lib/python3.10/site-packages/telegram/_bot.py", line 607, in _post
    return await self._do_post(
  File "/home/hokenz/.local/lib/python3.10/site-packages/telegram/ext/_extbot.py", line 347, in _do_post
    return await super()._do_post(
  File "/home/hokenz/.local/lib/python3.10/site-packages/telegram/_bot.py", line 635, in _do_post
    return await request.post(
  File "/home/hokenz/.local/lib/python3.10/site-packages/telegram/request/_baserequest.py", line 168, in post
    result = await self._request_wrapper(
  File "/home/hokenz/.local/lib/python3.10/site-packages/telegram/request/_baserequest.py", line 288, in _request_wrapper
    raise exc
  File "/home/hokenz/.local/lib/python3.10/site-packages/telegram/request/_baserequest.py", line 278, in _request_wrapper
    code, payload = await self.do_request(
  File "/home/hokenz/.local/lib/python3.10/site-packages/telegram/request/_httpxrequest.py", line 243, in do_request
    raise NetworkError(f"httpx.{err.__class__.__name__}: {err}") from err
telegram.error.NetworkError: httpx.ReadError: 
Error while getting Updates: httpx.ReadError: 
No error handlers are registered, logging exception.
Traceback (most recent call last):
  File "/home/hokenz/.local/lib/python3.10/site-packages/httpcore/_exceptions.py", line 10, in map_exceptions
    yield
  File "/home/hokenz/.local/lib/python3.10/site-packages/httpcore/_backends/anyio.py", line 34, in read
    return await self._stream.receive(max_bytes=max_bytes)
  File "/home/hokenz/.local/lib/python3.10/site-packages/anyio/streams/tls.py", line 198, in receive
    data = await self._call_sslobject_method(self._ssl_object.read, max_bytes)
  File "/home/hokenz/.local/lib/python3.10/site-packages/anyio/streams/tls.py", line 140, in _call_sslobject_method
    data = await self.transport_stream.receive()
  File "/home/hokenz/.local/lib/python3.10/site-packages/anyio/_backends/_asyncio.py", line 1104, in receive
    raise self._protocol.exception from None
anyio.BrokenResourceError

The above exception was the direct cause of the following exception:

Traceback (most recent call last):
  File "/home/hokenz/.local/lib/python3.10/site-packages/httpx/_transports/default.py", line 66, in map_httpcore_exceptions
    yield
  File "/home/hokenz/.local/lib/python3.10/site-packages/httpx/_transports/default.py", line 366, in handle_async_request
    resp = await self._pool.handle_async_request(req)
  File "/home/hokenz/.local/lib/python3.10/site-packages/httpcore/_async/connection_pool.py", line 268, in handle_async_request
    raise exc
  File "/home/hokenz/.local/lib/python3.10/site-packages/httpcore/_async/connection_pool.py", line 251, in handle_async_request
    response = await connection.handle_async_request(request)
  File "/home/hokenz/.local/lib/python3.10/site-packages/httpcore/_async/connection.py", line 103, in handle_async_request
    return await self._connection.handle_async_request(request)
  File "/home/hokenz/.local/lib/python3.10/site-packages/httpcore/_async/http11.py", line 133, in handle_async_request
    raise exc
  File "/home/hokenz/.local/lib/python3.10/site-packages/httpcore/_async/http11.py", line 111, in handle_async_request
    ) = await self._receive_response_headers(**kwargs)
  File "/home/hokenz/.local/lib/python3.10/site-packages/httpcore/_async/http11.py", line 176, in _receive_response_headers
    event = await self._receive_event(timeout=timeout)
  File "/home/hokenz/.local/lib/python3.10/site-packages/httpcore/_async/http11.py", line 212, in _receive_event
    data = await self._network_stream.read(
  File "/home/hokenz/.local/lib/python3.10/site-packages/httpcore/_backends/anyio.py", line 31, in read
    with map_exceptions(exc_map):
  File "/usr/lib/python3.10/contextlib.py", line 153, in __exit__
    self.gen.throw(typ, value, traceback)
  File "/home/hokenz/.local/lib/python3.10/site-packages/httpcore/_exceptions.py", line 14, in map_exceptions
    raise to_exc(exc) from exc
httpcore.ReadError

The above exception was the direct cause of the following exception:

Traceback (most recent call last):
  File "/home/hokenz/.local/lib/python3.10/site-packages/telegram/request/_httpxrequest.py", line 219, in do_request
    res = await self._client.request(
  File "/home/hokenz/.local/lib/python3.10/site-packages/httpx/_client.py", line 1530, in request
    return await self.send(request, auth=auth, follow_redirects=follow_redirects)
  File "/home/hokenz/.local/lib/python3.10/site-packages/httpx/_client.py", line 1617, in send
    response = await self._send_handling_auth(
  File "/home/hokenz/.local/lib/python3.10/site-packages/httpx/_client.py", line 1645, in _send_handling_auth
    response = await self._send_handling_redirects(
  File "/home/hokenz/.local/lib/python3.10/site-packages/httpx/_client.py", line 1682, in _send_handling_redirects
    response = await self._send_single_request(request)
  File "/home/hokenz/.local/lib/python3.10/site-packages/httpx/_client.py", line 1719, in _send_single_request
    response = await transport.handle_async_request(request)
  File "/home/hokenz/.local/lib/python3.10/site-packages/httpx/_transports/default.py", line 365, in handle_async_request
    with map_httpcore_exceptions():
  File "/usr/lib/python3.10/contextlib.py", line 153, in __exit__
    self.gen.throw(typ, value, traceback)
  File "/home/hokenz/.local/lib/python3.10/site-packages/httpx/_transports/default.py", line 83, in map_httpcore_exceptions
    raise mapped_exc(message) from exc
httpx.ReadError

The above exception was the direct cause of the following exception:

Traceback (most recent call last):
  File "/home/hokenz/.local/lib/python3.10/site-packages/telegram/ext/_updater.py", line 640, in _network_loop_retry
    if not await action_cb():
  File "/home/hokenz/.local/lib/python3.10/site-packages/telegram/ext/_updater.py", line 345, in polling_action_cb
    raise exc
  File "/home/hokenz/.local/lib/python3.10/site-packages/telegram/ext/_updater.py", line 334, in polling_action_cb
    updates = await self.bot.get_updates(
  File "/home/hokenz/.local/lib/python3.10/site-packages/telegram/ext/_extbot.py", line 565, in get_updates
    updates = await super().get_updates(
  File "/home/hokenz/.local/lib/python3.10/site-packages/telegram/_bot.py", line 519, in decorator
    result = await func(self, *args, **kwargs)  # skipcq: PYL-E1102
  File "/home/hokenz/.local/lib/python3.10/site-packages/telegram/_bot.py", line 3562, in get_updates
    await self._post(
  File "/home/hokenz/.local/lib/python3.10/site-packages/telegram/_bot.py", line 607, in _post
    return await self._do_post(
  File "/home/hokenz/.local/lib/python3.10/site-packages/telegram/ext/_extbot.py", line 347, in _do_post
    return await super()._do_post(
  File "/home/hokenz/.local/lib/python3.10/site-packages/telegram/_bot.py", line 635, in _do_post
    return await request.post(
  File "/home/hokenz/.local/lib/python3.10/site-packages/telegram/request/_baserequest.py", line 168, in post
    result = await self._request_wrapper(
  File "/home/hokenz/.local/lib/python3.10/site-packages/telegram/request/_baserequest.py", line 288, in _request_wrapper
    raise exc
  File "/home/hokenz/.local/lib/python3.10/site-packages/telegram/request/_baserequest.py", line 278, in _request_wrapper
    code, payload = await self.do_request(
  File "/home/hokenz/.local/lib/python3.10/site-packages/telegram/request/_httpxrequest.py", line 243, in do_request
    raise NetworkError(f"httpx.{err.__class__.__name__}: {err}") from err
telegram.error.NetworkError: httpx.ReadError: 
Error while getting Updates: httpx.ReadError: 
No error handlers are registered, logging exception.
Traceback (most recent call last):
  File "/home/hokenz/.local/lib/python3.10/site-packages/httpcore/_exceptions.py", line 10, in map_exceptions
    yield
  File "/home/hokenz/.local/lib/python3.10/site-packages/httpcore/_backends/anyio.py", line 34, in read
    return await self._stream.receive(max_bytes=max_bytes)
  File "/home/hokenz/.local/lib/python3.10/site-packages/anyio/streams/tls.py", line 198, in receive
    data = await self._call_sslobject_method(self._ssl_object.read, max_bytes)
  File "/home/hokenz/.local/lib/python3.10/site-packages/anyio/streams/tls.py", line 140, in _call_sslobject_method
    data = await self.transport_stream.receive()
  File "/home/hokenz/.local/lib/python3.10/site-packages/anyio/_backends/_asyncio.py", line 1104, in receive
    raise self._protocol.exception from None
anyio.BrokenResourceError

The above exception was the direct cause of the following exception:

Traceback (most recent call last):
  File "/home/hokenz/.local/lib/python3.10/site-packages/httpx/_transports/default.py", line 66, in map_httpcore_exceptions
    yield
  File "/home/hokenz/.local/lib/python3.10/site-packages/httpx/_transports/default.py", line 366, in handle_async_request
    resp = await self._pool.handle_async_request(req)
  File "/home/hokenz/.local/lib/python3.10/site-packages/httpcore/_async/connection_pool.py", line 268, in handle_async_request
    raise exc
  File "/home/hokenz/.local/lib/python3.10/site-packages/httpcore/_async/connection_pool.py", line 251, in handle_async_request
    response = await connection.handle_async_request(request)
  File "/home/hokenz/.local/lib/python3.10/site-packages/httpcore/_async/connection.py", line 103, in handle_async_request
    return await self._connection.handle_async_request(request)
  File "/home/hokenz/.local/lib/python3.10/site-packages/httpcore/_async/http11.py", line 133, in handle_async_request
    raise exc
  File "/home/hokenz/.local/lib/python3.10/site-packages/httpcore/_async/http11.py", line 111, in handle_async_request
    ) = await self._receive_response_headers(**kwargs)
  File "/home/hokenz/.local/lib/python3.10/site-packages/httpcore/_async/http11.py", line 176, in _receive_response_headers
    event = await self._receive_event(timeout=timeout)
  File "/home/hokenz/.local/lib/python3.10/site-packages/httpcore/_async/http11.py", line 212, in _receive_event
    data = await self._network_stream.read(
  File "/home/hokenz/.local/lib/python3.10/site-packages/httpcore/_backends/anyio.py", line 31, in read
    with map_exceptions(exc_map):
  File "/usr/lib/python3.10/contextlib.py", line 153, in __exit__
    self.gen.throw(typ, value, traceback)
  File "/home/hokenz/.local/lib/python3.10/site-packages/httpcore/_exceptions.py", line 14, in map_exceptions
    raise to_exc(exc) from exc
httpcore.ReadError

The above exception was the direct cause of the following exception:

Traceback (most recent call last):
  File "/home/hokenz/.local/lib/python3.10/site-packages/telegram/request/_httpxrequest.py", line 219, in do_request
    res = await self._client.request(
  File "/home/hokenz/.local/lib/python3.10/site-packages/httpx/_client.py", line 1530, in request
    return await self.send(request, auth=auth, follow_redirects=follow_redirects)
  File "/home/hokenz/.local/lib/python3.10/site-packages/httpx/_client.py", line 1617, in send
    response = await self._send_handling_auth(
  File "/home/hokenz/.local/lib/python3.10/site-packages/httpx/_client.py", line 1645, in _send_handling_auth
    response = await self._send_handling_redirects(
  File "/home/hokenz/.local/lib/python3.10/site-packages/httpx/_client.py", line 1682, in _send_handling_redirects
    response = await self._send_single_request(request)
  File "/home/hokenz/.local/lib/python3.10/site-packages/httpx/_client.py", line 1719, in _send_single_request
    response = await transport.handle_async_request(request)
  File "/home/hokenz/.local/lib/python3.10/site-packages/httpx/_transports/default.py", line 365, in handle_async_request
    with map_httpcore_exceptions():
  File "/usr/lib/python3.10/contextlib.py", line 153, in __exit__
    self.gen.throw(typ, value, traceback)
  File "/home/hokenz/.local/lib/python3.10/site-packages/httpx/_transports/default.py", line 83, in map_httpcore_exceptions
    raise mapped_exc(message) from exc
httpx.ReadError

The above exception was the direct cause of the following exception:

Traceback (most recent call last):
  File "/home/hokenz/.local/lib/python3.10/site-packages/telegram/ext/_updater.py", line 640, in _network_loop_retry
    if not await action_cb():
  File "/home/hokenz/.local/lib/python3.10/site-packages/telegram/ext/_updater.py", line 345, in polling_action_cb
    raise exc
  File "/home/hokenz/.local/lib/python3.10/site-packages/telegram/ext/_updater.py", line 334, in polling_action_cb
    updates = await self.bot.get_updates(
  File "/home/hokenz/.local/lib/python3.10/site-packages/telegram/ext/_extbot.py", line 565, in get_updates
    updates = await super().get_updates(
  File "/home/hokenz/.local/lib/python3.10/site-packages/telegram/_bot.py", line 519, in decorator
    result = await func(self, *args, **kwargs)  # skipcq: PYL-E1102
  File "/home/hokenz/.local/lib/python3.10/site-packages/telegram/_bot.py", line 3562, in get_updates
    await self._post(
  File "/home/hokenz/.local/lib/python3.10/site-packages/telegram/_bot.py", line 607, in _post
    return await self._do_post(
  File "/home/hokenz/.local/lib/python3.10/site-packages/telegram/ext/_extbot.py", line 347, in _do_post
    return await super()._do_post(
  File "/home/hokenz/.local/lib/python3.10/site-packages/telegram/_bot.py", line 635, in _do_post
    return await request.post(
  File "/home/hokenz/.local/lib/python3.10/site-packages/telegram/request/_baserequest.py", line 168, in post
    result = await self._request_wrapper(
  File "/home/hokenz/.local/lib/python3.10/site-packages/telegram/request/_baserequest.py", line 288, in _request_wrapper
    raise exc
  File "/home/hokenz/.local/lib/python3.10/site-packages/telegram/request/_baserequest.py", line 278, in _request_wrapper
    code, payload = await self.do_request(
  File "/home/hokenz/.local/lib/python3.10/site-packages/telegram/request/_httpxrequest.py", line 243, in do_request
    raise NetworkError(f"httpx.{err.__class__.__name__}: {err}") from err
telegram.error.NetworkError: httpx.ReadError: 
Error while getting Updates: httpx.ReadError: 
No error handlers are registered, logging exception.
Traceback (most recent call last):
  File "/home/hokenz/.local/lib/python3.10/site-packages/httpcore/_exceptions.py", line 10, in map_exceptions
    yield
  File "/home/hokenz/.local/lib/python3.10/site-packages/httpcore/_backends/anyio.py", line 34, in read
    return await self._stream.receive(max_bytes=max_bytes)
  File "/home/hokenz/.local/lib/python3.10/site-packages/anyio/streams/tls.py", line 198, in receive
    data = await self._call_sslobject_method(self._ssl_object.read, max_bytes)
  File "/home/hokenz/.local/lib/python3.10/site-packages/anyio/streams/tls.py", line 140, in _call_sslobject_method
    data = await self.transport_stream.receive()
  File "/home/hokenz/.local/lib/python3.10/site-packages/anyio/_backends/_asyncio.py", line 1104, in receive
    raise self._protocol.exception from None
anyio.BrokenResourceError

The above exception was the direct cause of the following exception:

Traceback (most recent call last):
  File "/home/hokenz/.local/lib/python3.10/site-packages/httpx/_transports/default.py", line 66, in map_httpcore_exceptions
    yield
  File "/home/hokenz/.local/lib/python3.10/site-packages/httpx/_transports/default.py", line 366, in handle_async_request
    resp = await self._pool.handle_async_request(req)
  File "/home/hokenz/.local/lib/python3.10/site-packages/httpcore/_async/connection_pool.py", line 268, in handle_async_request
    raise exc
  File "/home/hokenz/.local/lib/python3.10/site-packages/httpcore/_async/connection_pool.py", line 251, in handle_async_request
    response = await connection.handle_async_request(request)
  File "/home/hokenz/.local/lib/python3.10/site-packages/httpcore/_async/connection.py", line 103, in handle_async_request
    return await self._connection.handle_async_request(request)
  File "/home/hokenz/.local/lib/python3.10/site-packages/httpcore/_async/http11.py", line 133, in handle_async_request
    raise exc
  File "/home/hokenz/.local/lib/python3.10/site-packages/httpcore/_async/http11.py", line 111, in handle_async_request
    ) = await self._receive_response_headers(**kwargs)
  File "/home/hokenz/.local/lib/python3.10/site-packages/httpcore/_async/http11.py", line 176, in _receive_response_headers
    event = await self._receive_event(timeout=timeout)
  File "/home/hokenz/.local/lib/python3.10/site-packages/httpcore/_async/http11.py", line 212, in _receive_event
    data = await self._network_stream.read(
  File "/home/hokenz/.local/lib/python3.10/site-packages/httpcore/_backends/anyio.py", line 31, in read
    with map_exceptions(exc_map):
  File "/usr/lib/python3.10/contextlib.py", line 153, in __exit__
    self.gen.throw(typ, value, traceback)
  File "/home/hokenz/.local/lib/python3.10/site-packages/httpcore/_exceptions.py", line 14, in map_exceptions
    raise to_exc(exc) from exc
httpcore.ReadError

The above exception was the direct cause of the following exception:

Traceback (most recent call last):
  File "/home/hokenz/.local/lib/python3.10/site-packages/telegram/request/_httpxrequest.py", line 219, in do_request
    res = await self._client.request(
  File "/home/hokenz/.local/lib/python3.10/site-packages/httpx/_client.py", line 1530, in request
    return await self.send(request, auth=auth, follow_redirects=follow_redirects)
  File "/home/hokenz/.local/lib/python3.10/site-packages/httpx/_client.py", line 1617, in send
    response = await self._send_handling_auth(
  File "/home/hokenz/.local/lib/python3.10/site-packages/httpx/_client.py", line 1645, in _send_handling_auth
    response = await self._send_handling_redirects(
  File "/home/hokenz/.local/lib/python3.10/site-packages/httpx/_client.py", line 1682, in _send_handling_redirects
    response = await self._send_single_request(request)
  File "/home/hokenz/.local/lib/python3.10/site-packages/httpx/_client.py", line 1719, in _send_single_request
    response = await transport.handle_async_request(request)
  File "/home/hokenz/.local/lib/python3.10/site-packages/httpx/_transports/default.py", line 365, in handle_async_request
    with map_httpcore_exceptions():
  File "/usr/lib/python3.10/contextlib.py", line 153, in __exit__
    self.gen.throw(typ, value, traceback)
  File "/home/hokenz/.local/lib/python3.10/site-packages/httpx/_transports/default.py", line 83, in map_httpcore_exceptions
    raise mapped_exc(message) from exc
httpx.ReadError

The above exception was the direct cause of the following exception:

Traceback (most recent call last):
  File "/home/hokenz/.local/lib/python3.10/site-packages/telegram/ext/_updater.py", line 640, in _network_loop_retry
    if not await action_cb():
  File "/home/hokenz/.local/lib/python3.10/site-packages/telegram/ext/_updater.py", line 345, in polling_action_cb
    raise exc
  File "/home/hokenz/.local/lib/python3.10/site-packages/telegram/ext/_updater.py", line 334, in polling_action_cb
    updates = await self.bot.get_updates(
  File "/home/hokenz/.local/lib/python3.10/site-packages/telegram/ext/_extbot.py", line 565, in get_updates
    updates = await super().get_updates(
  File "/home/hokenz/.local/lib/python3.10/site-packages/telegram/_bot.py", line 519, in decorator
    result = await func(self, *args, **kwargs)  # skipcq: PYL-E1102
  File "/home/hokenz/.local/lib/python3.10/site-packages/telegram/_bot.py", line 3562, in get_updates
    await self._post(
  File "/home/hokenz/.local/lib/python3.10/site-packages/telegram/_bot.py", line 607, in _post
    return await self._do_post(
  File "/home/hokenz/.local/lib/python3.10/site-packages/telegram/ext/_extbot.py", line 347, in _do_post
    return await super()._do_post(
  File "/home/hokenz/.local/lib/python3.10/site-packages/telegram/_bot.py", line 635, in _do_post
    return await request.post(
  File "/home/hokenz/.local/lib/python3.10/site-packages/telegram/request/_baserequest.py", line 168, in post
    result = await self._request_wrapper(
  File "/home/hokenz/.local/lib/python3.10/site-packages/telegram/request/_baserequest.py", line 288, in _request_wrapper
    raise exc
  File "/home/hokenz/.local/lib/python3.10/site-packages/telegram/request/_baserequest.py", line 278, in _request_wrapper
    code, payload = await self.do_request(
  File "/home/hokenz/.local/lib/python3.10/site-packages/telegram/request/_httpxrequest.py", line 243, in do_request
    raise NetworkError(f"httpx.{err.__class__.__name__}: {err}") from err
telegram.error.NetworkError: httpx.ReadError: 
Error while getting Updates: httpx.ReadError: 
No error handlers are registered, logging exception.
Traceback (most recent call last):
  File "/home/hokenz/.local/lib/python3.10/site-packages/httpcore/_exceptions.py", line 10, in map_exceptions
    yield
  File "/home/hokenz/.local/lib/python3.10/site-packages/httpcore/_backends/anyio.py", line 34, in read
    return await self._stream.receive(max_bytes=max_bytes)
  File "/home/hokenz/.local/lib/python3.10/site-packages/anyio/streams/tls.py", line 198, in receive
    data = await self._call_sslobject_method(self._ssl_object.read, max_bytes)
  File "/home/hokenz/.local/lib/python3.10/site-packages/anyio/streams/tls.py", line 140, in _call_sslobject_method
    data = await self.transport_stream.receive()
  File "/home/hokenz/.local/lib/python3.10/site-packages/anyio/_backends/_asyncio.py", line 1104, in receive
    raise self._protocol.exception from None
anyio.BrokenResourceError

The above exception was the direct cause of the following exception:

Traceback (most recent call last):
  File "/home/hokenz/.local/lib/python3.10/site-packages/httpx/_transports/default.py", line 66, in map_httpcore_exceptions
    yield
  File "/home/hokenz/.local/lib/python3.10/site-packages/httpx/_transports/default.py", line 366, in handle_async_request
    resp = await self._pool.handle_async_request(req)
  File "/home/hokenz/.local/lib/python3.10/site-packages/httpcore/_async/connection_pool.py", line 268, in handle_async_request
    raise exc
  File "/home/hokenz/.local/lib/python3.10/site-packages/httpcore/_async/connection_pool.py", line 251, in handle_async_request
    response = await connection.handle_async_request(request)
  File "/home/hokenz/.local/lib/python3.10/site-packages/httpcore/_async/connection.py", line 103, in handle_async_request
    return await self._connection.handle_async_request(request)
  File "/home/hokenz/.local/lib/python3.10/site-packages/httpcore/_async/http11.py", line 133, in handle_async_request
    raise exc
  File "/home/hokenz/.local/lib/python3.10/site-packages/httpcore/_async/http11.py", line 111, in handle_async_request
    ) = await self._receive_response_headers(**kwargs)
  File "/home/hokenz/.local/lib/python3.10/site-packages/httpcore/_async/http11.py", line 176, in _receive_response_headers
    event = await self._receive_event(timeout=timeout)
  File "/home/hokenz/.local/lib/python3.10/site-packages/httpcore/_async/http11.py", line 212, in _receive_event
    data = await self._network_stream.read(
  File "/home/hokenz/.local/lib/python3.10/site-packages/httpcore/_backends/anyio.py", line 31, in read
    with map_exceptions(exc_map):
  File "/usr/lib/python3.10/contextlib.py", line 153, in __exit__
    self.gen.throw(typ, value, traceback)
  File "/home/hokenz/.local/lib/python3.10/site-packages/httpcore/_exceptions.py", line 14, in map_exceptions
    raise to_exc(exc) from exc
httpcore.ReadError

The above exception was the direct cause of the following exception:

Traceback (most recent call last):
  File "/home/hokenz/.local/lib/python3.10/site-packages/telegram/request/_httpxrequest.py", line 219, in do_request
    res = await self._client.request(
  File "/home/hokenz/.local/lib/python3.10/site-packages/httpx/_client.py", line 1530, in request
    return await self.send(request, auth=auth, follow_redirects=follow_redirects)
  File "/home/hokenz/.local/lib/python3.10/site-packages/httpx/_client.py", line 1617, in send
    response = await self._send_handling_auth(
  File "/home/hokenz/.local/lib/python3.10/site-packages/httpx/_client.py", line 1645, in _send_handling_auth
    response = await self._send_handling_redirects(
  File "/home/hokenz/.local/lib/python3.10/site-packages/httpx/_client.py", line 1682, in _send_handling_redirects
    response = await self._send_single_request(request)
  File "/home/hokenz/.local/lib/python3.10/site-packages/httpx/_client.py", line 1719, in _send_single_request
    response = await transport.handle_async_request(request)
  File "/home/hokenz/.local/lib/python3.10/site-packages/httpx/_transports/default.py", line 365, in handle_async_request
    with map_httpcore_exceptions():
  File "/usr/lib/python3.10/contextlib.py", line 153, in __exit__
    self.gen.throw(typ, value, traceback)
  File "/home/hokenz/.local/lib/python3.10/site-packages/httpx/_transports/default.py", line 83, in map_httpcore_exceptions
    raise mapped_exc(message) from exc
httpx.ReadError

The above exception was the direct cause of the following exception:

Traceback (most recent call last):
  File "/home/hokenz/.local/lib/python3.10/site-packages/telegram/ext/_updater.py", line 640, in _network_loop_retry
    if not await action_cb():
  File "/home/hokenz/.local/lib/python3.10/site-packages/telegram/ext/_updater.py", line 345, in polling_action_cb
    raise exc
  File "/home/hokenz/.local/lib/python3.10/site-packages/telegram/ext/_updater.py", line 334, in polling_action_cb
    updates = await self.bot.get_updates(
  File "/home/hokenz/.local/lib/python3.10/site-packages/telegram/ext/_extbot.py", line 565, in get_updates
    updates = await super().get_updates(
  File "/home/hokenz/.local/lib/python3.10/site-packages/telegram/_bot.py", line 519, in decorator
    result = await func(self, *args, **kwargs)  # skipcq: PYL-E1102
  File "/home/hokenz/.local/lib/python3.10/site-packages/telegram/_bot.py", line 3562, in get_updates
    await self._post(
  File "/home/hokenz/.local/lib/python3.10/site-packages/telegram/_bot.py", line 607, in _post
    return await self._do_post(
  File "/home/hokenz/.local/lib/python3.10/site-packages/telegram/ext/_extbot.py", line 347, in _do_post
    return await super()._do_post(
  File "/home/hokenz/.local/lib/python3.10/site-packages/telegram/_bot.py", line 635, in _do_post
    return await request.post(
  File "/home/hokenz/.local/lib/python3.10/site-packages/telegram/request/_baserequest.py", line 168, in post
    result = await self._request_wrapper(
  File "/home/hokenz/.local/lib/python3.10/site-packages/telegram/request/_baserequest.py", line 288, in _request_wrapper
    raise exc
  File "/home/hokenz/.local/lib/python3.10/site-packages/telegram/request/_baserequest.py", line 278, in _request_wrapper
    code, payload = await self.do_request(
  File "/home/hokenz/.local/lib/python3.10/site-packages/telegram/request/_httpxrequest.py", line 243, in do_request
    raise NetworkError(f"httpx.{err.__class__.__name__}: {err}") from err
telegram.error.NetworkError: httpx.ReadError: 
Error while getting Updates: httpx.ReadError: 
No error handlers are registered, logging exception.
Traceback (most recent call last):
  File "/home/hokenz/.local/lib/python3.10/site-packages/httpcore/_exceptions.py", line 10, in map_exceptions
    yield
  File "/home/hokenz/.local/lib/python3.10/site-packages/httpcore/_backends/anyio.py", line 34, in read
    return await self._stream.receive(max_bytes=max_bytes)
  File "/home/hokenz/.local/lib/python3.10/site-packages/anyio/streams/tls.py", line 198, in receive
    data = await self._call_sslobject_method(self._ssl_object.read, max_bytes)
  File "/home/hokenz/.local/lib/python3.10/site-packages/anyio/streams/tls.py", line 140, in _call_sslobject_method
    data = await self.transport_stream.receive()
  File "/home/hokenz/.local/lib/python3.10/site-packages/anyio/_backends/_asyncio.py", line 1104, in receive
    raise self._protocol.exception from None
anyio.BrokenResourceError

The above exception was the direct cause of the following exception:

Traceback (most recent call last):
  File "/home/hokenz/.local/lib/python3.10/site-packages/httpx/_transports/default.py", line 66, in map_httpcore_exceptions
    yield
  File "/home/hokenz/.local/lib/python3.10/site-packages/httpx/_transports/default.py", line 366, in handle_async_request
    resp = await self._pool.handle_async_request(req)
  File "/home/hokenz/.local/lib/python3.10/site-packages/httpcore/_async/connection_pool.py", line 268, in handle_async_request
    raise exc
  File "/home/hokenz/.local/lib/python3.10/site-packages/httpcore/_async/connection_pool.py", line 251, in handle_async_request
    response = await connection.handle_async_request(request)
  File "/home/hokenz/.local/lib/python3.10/site-packages/httpcore/_async/connection.py", line 103, in handle_async_request
    return await self._connection.handle_async_request(request)
  File "/home/hokenz/.local/lib/python3.10/site-packages/httpcore/_async/http11.py", line 133, in handle_async_request
    raise exc
  File "/home/hokenz/.local/lib/python3.10/site-packages/httpcore/_async/http11.py", line 111, in handle_async_request
    ) = await self._receive_response_headers(**kwargs)
  File "/home/hokenz/.local/lib/python3.10/site-packages/httpcore/_async/http11.py", line 176, in _receive_response_headers
    event = await self._receive_event(timeout=timeout)
  File "/home/hokenz/.local/lib/python3.10/site-packages/httpcore/_async/http11.py", line 212, in _receive_event
    data = await self._network_stream.read(
  File "/home/hokenz/.local/lib/python3.10/site-packages/httpcore/_backends/anyio.py", line 31, in read
    with map_exceptions(exc_map):
  File "/usr/lib/python3.10/contextlib.py", line 153, in __exit__
    self.gen.throw(typ, value, traceback)
  File "/home/hokenz/.local/lib/python3.10/site-packages/httpcore/_exceptions.py", line 14, in map_exceptions
    raise to_exc(exc) from exc
httpcore.ReadError

The above exception was the direct cause of the following exception:

Traceback (most recent call last):
  File "/home/hokenz/.local/lib/python3.10/site-packages/telegram/request/_httpxrequest.py", line 219, in do_request
    res = await self._client.request(
  File "/home/hokenz/.local/lib/python3.10/site-packages/httpx/_client.py", line 1530, in request
    return await self.send(request, auth=auth, follow_redirects=follow_redirects)
  File "/home/hokenz/.local/lib/python3.10/site-packages/httpx/_client.py", line 1617, in send
    response = await self._send_handling_auth(
  File "/home/hokenz/.local/lib/python3.10/site-packages/httpx/_client.py", line 1645, in _send_handling_auth
    response = await self._send_handling_redirects(
  File "/home/hokenz/.local/lib/python3.10/site-packages/httpx/_client.py", line 1682, in _send_handling_redirects
    response = await self._send_single_request(request)
  File "/home/hokenz/.local/lib/python3.10/site-packages/httpx/_client.py", line 1719, in _send_single_request
    response = await transport.handle_async_request(request)
  File "/home/hokenz/.local/lib/python3.10/site-packages/httpx/_transports/default.py", line 365, in handle_async_request
    with map_httpcore_exceptions():
  File "/usr/lib/python3.10/contextlib.py", line 153, in __exit__
    self.gen.throw(typ, value, traceback)
  File "/home/hokenz/.local/lib/python3.10/site-packages/httpx/_transports/default.py", line 83, in map_httpcore_exceptions
    raise mapped_exc(message) from exc
httpx.ReadError

The above exception was the direct cause of the following exception:

Traceback (most recent call last):
  File "/home/hokenz/.local/lib/python3.10/site-packages/telegram/ext/_updater.py", line 640, in _network_loop_retry
    if not await action_cb():
  File "/home/hokenz/.local/lib/python3.10/site-packages/telegram/ext/_updater.py", line 345, in polling_action_cb
    raise exc
  File "/home/hokenz/.local/lib/python3.10/site-packages/telegram/ext/_updater.py", line 334, in polling_action_cb
    updates = await self.bot.get_updates(
  File "/home/hokenz/.local/lib/python3.10/site-packages/telegram/ext/_extbot.py", line 565, in get_updates
    updates = await super().get_updates(
  File "/home/hokenz/.local/lib/python3.10/site-packages/telegram/_bot.py", line 519, in decorator
    result = await func(self, *args, **kwargs)  # skipcq: PYL-E1102
  File "/home/hokenz/.local/lib/python3.10/site-packages/telegram/_bot.py", line 3562, in get_updates
    await self._post(
  File "/home/hokenz/.local/lib/python3.10/site-packages/telegram/_bot.py", line 607, in _post
    return await self._do_post(
  File "/home/hokenz/.local/lib/python3.10/site-packages/telegram/ext/_extbot.py", line 347, in _do_post
    return await super()._do_post(
  File "/home/hokenz/.local/lib/python3.10/site-packages/telegram/_bot.py", line 635, in _do_post
    return await request.post(
  File "/home/hokenz/.local/lib/python3.10/site-packages/telegram/request/_baserequest.py", line 168, in post
    result = await self._request_wrapper(
  File "/home/hokenz/.local/lib/python3.10/site-packages/telegram/request/_baserequest.py", line 288, in _request_wrapper
    raise exc
  File "/home/hokenz/.local/lib/python3.10/site-packages/telegram/request/_baserequest.py", line 278, in _request_wrapper
    code, payload = await self.do_request(
  File "/home/hokenz/.local/lib/python3.10/site-packages/telegram/request/_httpxrequest.py", line 243, in do_request
    raise NetworkError(f"httpx.{err.__class__.__name__}: {err}") from err
telegram.error.NetworkError: httpx.ReadError: 
Error while getting Updates: httpx.ReadError: 
No error handlers are registered, logging exception.
Traceback (most recent call last):
  File "/home/hokenz/.local/lib/python3.10/site-packages/httpcore/_exceptions.py", line 10, in map_exceptions
    yield
  File "/home/hokenz/.local/lib/python3.10/site-packages/httpcore/_backends/anyio.py", line 34, in read
    return await self._stream.receive(max_bytes=max_bytes)
  File "/home/hokenz/.local/lib/python3.10/site-packages/anyio/streams/tls.py", line 198, in receive
    data = await self._call_sslobject_method(self._ssl_object.read, max_bytes)
  File "/home/hokenz/.local/lib/python3.10/site-packages/anyio/streams/tls.py", line 140, in _call_sslobject_method
    data = await self.transport_stream.receive()
  File "/home/hokenz/.local/lib/python3.10/site-packages/anyio/_backends/_asyncio.py", line 1104, in receive
    raise self._protocol.exception from None
anyio.BrokenResourceError

The above exception was the direct cause of the following exception:

Traceback (most recent call last):
  File "/home/hokenz/.local/lib/python3.10/site-packages/httpx/_transports/default.py", line 66, in map_httpcore_exceptions
    yield
  File "/home/hokenz/.local/lib/python3.10/site-packages/httpx/_transports/default.py", line 366, in handle_async_request
    resp = await self._pool.handle_async_request(req)
  File "/home/hokenz/.local/lib/python3.10/site-packages/httpcore/_async/connection_pool.py", line 268, in handle_async_request
    raise exc
  File "/home/hokenz/.local/lib/python3.10/site-packages/httpcore/_async/connection_pool.py", line 251, in handle_async_request
    response = await connection.handle_async_request(request)
  File "/home/hokenz/.local/lib/python3.10/site-packages/httpcore/_async/connection.py", line 103, in handle_async_request
    return await self._connection.handle_async_request(request)
  File "/home/hokenz/.local/lib/python3.10/site-packages/httpcore/_async/http11.py", line 133, in handle_async_request
    raise exc
  File "/home/hokenz/.local/lib/python3.10/site-packages/httpcore/_async/http11.py", line 111, in handle_async_request
    ) = await self._receive_response_headers(**kwargs)
  File "/home/hokenz/.local/lib/python3.10/site-packages/httpcore/_async/http11.py", line 176, in _receive_response_headers
    event = await self._receive_event(timeout=timeout)
  File "/home/hokenz/.local/lib/python3.10/site-packages/httpcore/_async/http11.py", line 212, in _receive_event
    data = await self._network_stream.read(
  File "/home/hokenz/.local/lib/python3.10/site-packages/httpcore/_backends/anyio.py", line 31, in read
    with map_exceptions(exc_map):
  File "/usr/lib/python3.10/contextlib.py", line 153, in __exit__
    self.gen.throw(typ, value, traceback)
  File "/home/hokenz/.local/lib/python3.10/site-packages/httpcore/_exceptions.py", line 14, in map_exceptions
    raise to_exc(exc) from exc
httpcore.ReadError

The above exception was the direct cause of the following exception:

Traceback (most recent call last):
  File "/home/hokenz/.local/lib/python3.10/site-packages/telegram/request/_httpxrequest.py", line 219, in do_request
    res = await self._client.request(
  File "/home/hokenz/.local/lib/python3.10/site-packages/httpx/_client.py", line 1530, in request
    return await self.send(request, auth=auth, follow_redirects=follow_redirects)
  File "/home/hokenz/.local/lib/python3.10/site-packages/httpx/_client.py", line 1617, in send
    response = await self._send_handling_auth(
  File "/home/hokenz/.local/lib/python3.10/site-packages/httpx/_client.py", line 1645, in _send_handling_auth
    response = await self._send_handling_redirects(
  File "/home/hokenz/.local/lib/python3.10/site-packages/httpx/_client.py", line 1682, in _send_handling_redirects
    response = await self._send_single_request(request)
  File "/home/hokenz/.local/lib/python3.10/site-packages/httpx/_client.py", line 1719, in _send_single_request
    response = await transport.handle_async_request(request)
  File "/home/hokenz/.local/lib/python3.10/site-packages/httpx/_transports/default.py", line 365, in handle_async_request
    with map_httpcore_exceptions():
  File "/usr/lib/python3.10/contextlib.py", line 153, in __exit__
    self.gen.throw(typ, value, traceback)
  File "/home/hokenz/.local/lib/python3.10/site-packages/httpx/_transports/default.py", line 83, in map_httpcore_exceptions
    raise mapped_exc(message) from exc
httpx.ReadError

The above exception was the direct cause of the following exception:

Traceback (most recent call last):
  File "/home/hokenz/.local/lib/python3.10/site-packages/telegram/ext/_updater.py", line 640, in _network_loop_retry
    if not await action_cb():
  File "/home/hokenz/.local/lib/python3.10/site-packages/telegram/ext/_updater.py", line 345, in polling_action_cb
    raise exc
  File "/home/hokenz/.local/lib/python3.10/site-packages/telegram/ext/_updater.py", line 334, in polling_action_cb
    updates = await self.bot.get_updates(
  File "/home/hokenz/.local/lib/python3.10/site-packages/telegram/ext/_extbot.py", line 565, in get_updates
    updates = await super().get_updates(
  File "/home/hokenz/.local/lib/python3.10/site-packages/telegram/_bot.py", line 519, in decorator
    result = await func(self, *args, **kwargs)  # skipcq: PYL-E1102
  File "/home/hokenz/.local/lib/python3.10/site-packages/telegram/_bot.py", line 3562, in get_updates
    await self._post(
  File "/home/hokenz/.local/lib/python3.10/site-packages/telegram/_bot.py", line 607, in _post
    return await self._do_post(
  File "/home/hokenz/.local/lib/python3.10/site-packages/telegram/ext/_extbot.py", line 347, in _do_post
    return await super()._do_post(
  File "/home/hokenz/.local/lib/python3.10/site-packages/telegram/_bot.py", line 635, in _do_post
    return await request.post(
  File "/home/hokenz/.local/lib/python3.10/site-packages/telegram/request/_baserequest.py", line 168, in post
    result = await self._request_wrapper(
  File "/home/hokenz/.local/lib/python3.10/site-packages/telegram/request/_baserequest.py", line 288, in _request_wrapper
    raise exc
  File "/home/hokenz/.local/lib/python3.10/site-packages/telegram/request/_baserequest.py", line 278, in _request_wrapper
    code, payload = await self.do_request(
  File "/home/hokenz/.local/lib/python3.10/site-packages/telegram/request/_httpxrequest.py", line 243, in do_request
    raise NetworkError(f"httpx.{err.__class__.__name__}: {err}") from err
telegram.error.NetworkError: httpx.ReadError: 
Error while getting Updates: httpx.ReadError: 
No error handlers are registered, logging exception.
Traceback (most recent call last):
  File "/home/hokenz/.local/lib/python3.10/site-packages/httpcore/_exceptions.py", line 10, in map_exceptions
    yield
  File "/home/hokenz/.local/lib/python3.10/site-packages/httpcore/_backends/anyio.py", line 34, in read
    return await self._stream.receive(max_bytes=max_bytes)
  File "/home/hokenz/.local/lib/python3.10/site-packages/anyio/streams/tls.py", line 198, in receive
    data = await self._call_sslobject_method(self._ssl_object.read, max_bytes)
  File "/home/hokenz/.local/lib/python3.10/site-packages/anyio/streams/tls.py", line 140, in _call_sslobject_method
    data = await self.transport_stream.receive()
  File "/home/hokenz/.local/lib/python3.10/site-packages/anyio/_backends/_asyncio.py", line 1104, in receive
    raise self._protocol.exception from None
anyio.BrokenResourceError

The above exception was the direct cause of the following exception:

Traceback (most recent call last):
  File "/home/hokenz/.local/lib/python3.10/site-packages/httpx/_transports/default.py", line 66, in map_httpcore_exceptions
    yield
  File "/home/hokenz/.local/lib/python3.10/site-packages/httpx/_transports/default.py", line 366, in handle_async_request
    resp = await self._pool.handle_async_request(req)
  File "/home/hokenz/.local/lib/python3.10/site-packages/httpcore/_async/connection_pool.py", line 268, in handle_async_request
    raise exc
  File "/home/hokenz/.local/lib/python3.10/site-packages/httpcore/_async/connection_pool.py", line 251, in handle_async_request
    response = await connection.handle_async_request(request)
  File "/home/hokenz/.local/lib/python3.10/site-packages/httpcore/_async/connection.py", line 103, in handle_async_request
    return await self._connection.handle_async_request(request)
  File "/home/hokenz/.local/lib/python3.10/site-packages/httpcore/_async/http11.py", line 133, in handle_async_request
    raise exc
  File "/home/hokenz/.local/lib/python3.10/site-packages/httpcore/_async/http11.py", line 111, in handle_async_request
    ) = await self._receive_response_headers(**kwargs)
  File "/home/hokenz/.local/lib/python3.10/site-packages/httpcore/_async/http11.py", line 176, in _receive_response_headers
    event = await self._receive_event(timeout=timeout)
  File "/home/hokenz/.local/lib/python3.10/site-packages/httpcore/_async/http11.py", line 212, in _receive_event
    data = await self._network_stream.read(
  File "/home/hokenz/.local/lib/python3.10/site-packages/httpcore/_backends/anyio.py", line 31, in read
    with map_exceptions(exc_map):
  File "/usr/lib/python3.10/contextlib.py", line 153, in __exit__
    self.gen.throw(typ, value, traceback)
  File "/home/hokenz/.local/lib/python3.10/site-packages/httpcore/_exceptions.py", line 14, in map_exceptions
    raise to_exc(exc) from exc
httpcore.ReadError

The above exception was the direct cause of the following exception:

Traceback (most recent call last):
  File "/home/hokenz/.local/lib/python3.10/site-packages/telegram/request/_httpxrequest.py", line 219, in do_request
    res = await self._client.request(
  File "/home/hokenz/.local/lib/python3.10/site-packages/httpx/_client.py", line 1530, in request
    return await self.send(request, auth=auth, follow_redirects=follow_redirects)
  File "/home/hokenz/.local/lib/python3.10/site-packages/httpx/_client.py", line 1617, in send
    response = await self._send_handling_auth(
  File "/home/hokenz/.local/lib/python3.10/site-packages/httpx/_client.py", line 1645, in _send_handling_auth
    response = await self._send_handling_redirects(
  File "/home/hokenz/.local/lib/python3.10/site-packages/httpx/_client.py", line 1682, in _send_handling_redirects
    response = await self._send_single_request(request)
  File "/home/hokenz/.local/lib/python3.10/site-packages/httpx/_client.py", line 1719, in _send_single_request
    response = await transport.handle_async_request(request)
  File "/home/hokenz/.local/lib/python3.10/site-packages/httpx/_transports/default.py", line 365, in handle_async_request
    with map_httpcore_exceptions():
  File "/usr/lib/python3.10/contextlib.py", line 153, in __exit__
    self.gen.throw(typ, value, traceback)
  File "/home/hokenz/.local/lib/python3.10/site-packages/httpx/_transports/default.py", line 83, in map_httpcore_exceptions
    raise mapped_exc(message) from exc
httpx.ReadError

The above exception was the direct cause of the following exception:

Traceback (most recent call last):
  File "/home/hokenz/.local/lib/python3.10/site-packages/telegram/ext/_updater.py", line 640, in _network_loop_retry
    if not await action_cb():
  File "/home/hokenz/.local/lib/python3.10/site-packages/telegram/ext/_updater.py", line 345, in polling_action_cb
    raise exc
  File "/home/hokenz/.local/lib/python3.10/site-packages/telegram/ext/_updater.py", line 334, in polling_action_cb
    updates = await self.bot.get_updates(
  File "/home/hokenz/.local/lib/python3.10/site-packages/telegram/ext/_extbot.py", line 565, in get_updates
    updates = await super().get_updates(
  File "/home/hokenz/.local/lib/python3.10/site-packages/telegram/_bot.py", line 519, in decorator
    result = await func(self, *args, **kwargs)  # skipcq: PYL-E1102
  File "/home/hokenz/.local/lib/python3.10/site-packages/telegram/_bot.py", line 3562, in get_updates
    await self._post(
  File "/home/hokenz/.local/lib/python3.10/site-packages/telegram/_bot.py", line 607, in _post
    return await self._do_post(
  File "/home/hokenz/.local/lib/python3.10/site-packages/telegram/ext/_extbot.py", line 347, in _do_post
    return await super()._do_post(
  File "/home/hokenz/.local/lib/python3.10/site-packages/telegram/_bot.py", line 635, in _do_post
    return await request.post(
  File "/home/hokenz/.local/lib/python3.10/site-packages/telegram/request/_baserequest.py", line 168, in post
    result = await self._request_wrapper(
  File "/home/hokenz/.local/lib/python3.10/site-packages/telegram/request/_baserequest.py", line 288, in _request_wrapper
    raise exc
  File "/home/hokenz/.local/lib/python3.10/site-packages/telegram/request/_baserequest.py", line 278, in _request_wrapper
    code, payload = await self.do_request(
  File "/home/hokenz/.local/lib/python3.10/site-packages/telegram/request/_httpxrequest.py", line 243, in do_request
    raise NetworkError(f"httpx.{err.__class__.__name__}: {err}") from err
telegram.error.NetworkError: httpx.ReadError: 
Error while getting Updates: httpx.ReadError: 
No error handlers are registered, logging exception.
Traceback (most recent call last):
  File "/home/hokenz/.local/lib/python3.10/site-packages/httpcore/_exceptions.py", line 10, in map_exceptions
    yield
  File "/home/hokenz/.local/lib/python3.10/site-packages/httpcore/_backends/anyio.py", line 34, in read
    return await self._stream.receive(max_bytes=max_bytes)
  File "/home/hokenz/.local/lib/python3.10/site-packages/anyio/streams/tls.py", line 198, in receive
    data = await self._call_sslobject_method(self._ssl_object.read, max_bytes)
  File "/home/hokenz/.local/lib/python3.10/site-packages/anyio/streams/tls.py", line 140, in _call_sslobject_method
    data = await self.transport_stream.receive()
  File "/home/hokenz/.local/lib/python3.10/site-packages/anyio/_backends/_asyncio.py", line 1104, in receive
    raise self._protocol.exception from None
anyio.BrokenResourceError

The above exception was the direct cause of the following exception:

Traceback (most recent call last):
  File "/home/hokenz/.local/lib/python3.10/site-packages/httpx/_transports/default.py", line 66, in map_httpcore_exceptions
    yield
  File "/home/hokenz/.local/lib/python3.10/site-packages/httpx/_transports/default.py", line 366, in handle_async_request
    resp = await self._pool.handle_async_request(req)
  File "/home/hokenz/.local/lib/python3.10/site-packages/httpcore/_async/connection_pool.py", line 268, in handle_async_request
    raise exc
  File "/home/hokenz/.local/lib/python3.10/site-packages/httpcore/_async/connection_pool.py", line 251, in handle_async_request
    response = await connection.handle_async_request(request)
  File "/home/hokenz/.local/lib/python3.10/site-packages/httpcore/_async/connection.py", line 103, in handle_async_request
    return await self._connection.handle_async_request(request)
  File "/home/hokenz/.local/lib/python3.10/site-packages/httpcore/_async/http11.py", line 133, in handle_async_request
    raise exc
  File "/home/hokenz/.local/lib/python3.10/site-packages/httpcore/_async/http11.py", line 111, in handle_async_request
    ) = await self._receive_response_headers(**kwargs)
  File "/home/hokenz/.local/lib/python3.10/site-packages/httpcore/_async/http11.py", line 176, in _receive_response_headers
    event = await self._receive_event(timeout=timeout)
  File "/home/hokenz/.local/lib/python3.10/site-packages/httpcore/_async/http11.py", line 212, in _receive_event
    data = await self._network_stream.read(
  File "/home/hokenz/.local/lib/python3.10/site-packages/httpcore/_backends/anyio.py", line 31, in read
    with map_exceptions(exc_map):
  File "/usr/lib/python3.10/contextlib.py", line 153, in __exit__
    self.gen.throw(typ, value, traceback)
  File "/home/hokenz/.local/lib/python3.10/site-packages/httpcore/_exceptions.py", line 14, in map_exceptions
    raise to_exc(exc) from exc
httpcore.ReadError

The above exception was the direct cause of the following exception:

Traceback (most recent call last):
  File "/home/hokenz/.local/lib/python3.10/site-packages/telegram/request/_httpxrequest.py", line 219, in do_request
    res = await self._client.request(
  File "/home/hokenz/.local/lib/python3.10/site-packages/httpx/_client.py", line 1530, in request
    return await self.send(request, auth=auth, follow_redirects=follow_redirects)
  File "/home/hokenz/.local/lib/python3.10/site-packages/httpx/_client.py", line 1617, in send
    response = await self._send_handling_auth(
  File "/home/hokenz/.local/lib/python3.10/site-packages/httpx/_client.py", line 1645, in _send_handling_auth
    response = await self._send_handling_redirects(
  File "/home/hokenz/.local/lib/python3.10/site-packages/httpx/_client.py", line 1682, in _send_handling_redirects
    response = await self._send_single_request(request)
  File "/home/hokenz/.local/lib/python3.10/site-packages/httpx/_client.py", line 1719, in _send_single_request
    response = await transport.handle_async_request(request)
  File "/home/hokenz/.local/lib/python3.10/site-packages/httpx/_transports/default.py", line 365, in handle_async_request
    with map_httpcore_exceptions():
  File "/usr/lib/python3.10/contextlib.py", line 153, in __exit__
    self.gen.throw(typ, value, traceback)
  File "/home/hokenz/.local/lib/python3.10/site-packages/httpx/_transports/default.py", line 83, in map_httpcore_exceptions
    raise mapped_exc(message) from exc
httpx.ReadError

The above exception was the direct cause of the following exception:

Traceback (most recent call last):
  File "/home/hokenz/.local/lib/python3.10/site-packages/telegram/ext/_updater.py", line 640, in _network_loop_retry
    if not await action_cb():
  File "/home/hokenz/.local/lib/python3.10/site-packages/telegram/ext/_updater.py", line 345, in polling_action_cb
    raise exc
  File "/home/hokenz/.local/lib/python3.10/site-packages/telegram/ext/_updater.py", line 334, in polling_action_cb
    updates = await self.bot.get_updates(
  File "/home/hokenz/.local/lib/python3.10/site-packages/telegram/ext/_extbot.py", line 565, in get_updates
    updates = await super().get_updates(
  File "/home/hokenz/.local/lib/python3.10/site-packages/telegram/_bot.py", line 519, in decorator
    result = await func(self, *args, **kwargs)  # skipcq: PYL-E1102
  File "/home/hokenz/.local/lib/python3.10/site-packages/telegram/_bot.py", line 3562, in get_updates
    await self._post(
  File "/home/hokenz/.local/lib/python3.10/site-packages/telegram/_bot.py", line 607, in _post
    return await self._do_post(
  File "/home/hokenz/.local/lib/python3.10/site-packages/telegram/ext/_extbot.py", line 347, in _do_post
    return await super()._do_post(
  File "/home/hokenz/.local/lib/python3.10/site-packages/telegram/_bot.py", line 635, in _do_post
    return await request.post(
  File "/home/hokenz/.local/lib/python3.10/site-packages/telegram/request/_baserequest.py", line 168, in post
    result = await self._request_wrapper(
  File "/home/hokenz/.local/lib/python3.10/site-packages/telegram/request/_baserequest.py", line 288, in _request_wrapper
    raise exc
  File "/home/hokenz/.local/lib/python3.10/site-packages/telegram/request/_baserequest.py", line 278, in _request_wrapper
    code, payload = await self.do_request(
  File "/home/hokenz/.local/lib/python3.10/site-packages/telegram/request/_httpxrequest.py", line 243, in do_request
    raise NetworkError(f"httpx.{err.__class__.__name__}: {err}") from err
telegram.error.NetworkError: httpx.ReadError: 
Error while getting Updates: httpx.ReadError: 
No error handlers are registered, logging exception.
Traceback (most recent call last):
  File "/home/hokenz/.local/lib/python3.10/site-packages/httpcore/_exceptions.py", line 10, in map_exceptions
    yield
  File "/home/hokenz/.local/lib/python3.10/site-packages/httpcore/_backends/anyio.py", line 34, in read
    return await self._stream.receive(max_bytes=max_bytes)
  File "/home/hokenz/.local/lib/python3.10/site-packages/anyio/streams/tls.py", line 198, in receive
    data = await self._call_sslobject_method(self._ssl_object.read, max_bytes)
  File "/home/hokenz/.local/lib/python3.10/site-packages/anyio/streams/tls.py", line 140, in _call_sslobject_method
    data = await self.transport_stream.receive()
  File "/home/hokenz/.local/lib/python3.10/site-packages/anyio/_backends/_asyncio.py", line 1104, in receive
    raise self._protocol.exception from None
anyio.BrokenResourceError

The above exception was the direct cause of the following exception:

Traceback (most recent call last):
  File "/home/hokenz/.local/lib/python3.10/site-packages/httpx/_transports/default.py", line 66, in map_httpcore_exceptions
    yield
  File "/home/hokenz/.local/lib/python3.10/site-packages/httpx/_transports/default.py", line 366, in handle_async_request
    resp = await self._pool.handle_async_request(req)
  File "/home/hokenz/.local/lib/python3.10/site-packages/httpcore/_async/connection_pool.py", line 268, in handle_async_request
    raise exc
  File "/home/hokenz/.local/lib/python3.10/site-packages/httpcore/_async/connection_pool.py", line 251, in handle_async_request
    response = await connection.handle_async_request(request)
  File "/home/hokenz/.local/lib/python3.10/site-packages/httpcore/_async/connection.py", line 103, in handle_async_request
    return await self._connection.handle_async_request(request)
  File "/home/hokenz/.local/lib/python3.10/site-packages/httpcore/_async/http11.py", line 133, in handle_async_request
    raise exc
  File "/home/hokenz/.local/lib/python3.10/site-packages/httpcore/_async/http11.py", line 111, in handle_async_request
    ) = await self._receive_response_headers(**kwargs)
  File "/home/hokenz/.local/lib/python3.10/site-packages/httpcore/_async/http11.py", line 176, in _receive_response_headers
    event = await self._receive_event(timeout=timeout)
  File "/home/hokenz/.local/lib/python3.10/site-packages/httpcore/_async/http11.py", line 212, in _receive_event
    data = await self._network_stream.read(
  File "/home/hokenz/.local/lib/python3.10/site-packages/httpcore/_backends/anyio.py", line 31, in read
    with map_exceptions(exc_map):
  File "/usr/lib/python3.10/contextlib.py", line 153, in __exit__
    self.gen.throw(typ, value, traceback)
  File "/home/hokenz/.local/lib/python3.10/site-packages/httpcore/_exceptions.py", line 14, in map_exceptions
    raise to_exc(exc) from exc
httpcore.ReadError

The above exception was the direct cause of the following exception:

Traceback (most recent call last):
  File "/home/hokenz/.local/lib/python3.10/site-packages/telegram/request/_httpxrequest.py", line 219, in do_request
    res = await self._client.request(
  File "/home/hokenz/.local/lib/python3.10/site-packages/httpx/_client.py", line 1530, in request
    return await self.send(request, auth=auth, follow_redirects=follow_redirects)
  File "/home/hokenz/.local/lib/python3.10/site-packages/httpx/_client.py", line 1617, in send
    response = await self._send_handling_auth(
  File "/home/hokenz/.local/lib/python3.10/site-packages/httpx/_client.py", line 1645, in _send_handling_auth
    response = await self._send_handling_redirects(
  File "/home/hokenz/.local/lib/python3.10/site-packages/httpx/_client.py", line 1682, in _send_handling_redirects
    response = await self._send_single_request(request)
  File "/home/hokenz/.local/lib/python3.10/site-packages/httpx/_client.py", line 1719, in _send_single_request
    response = await transport.handle_async_request(request)
  File "/home/hokenz/.local/lib/python3.10/site-packages/httpx/_transports/default.py", line 365, in handle_async_request
    with map_httpcore_exceptions():
  File "/usr/lib/python3.10/contextlib.py", line 153, in __exit__
    self.gen.throw(typ, value, traceback)
  File "/home/hokenz/.local/lib/python3.10/site-packages/httpx/_transports/default.py", line 83, in map_httpcore_exceptions
    raise mapped_exc(message) from exc
httpx.ReadError

The above exception was the direct cause of the following exception:

Traceback (most recent call last):
  File "/home/hokenz/.local/lib/python3.10/site-packages/telegram/ext/_updater.py", line 640, in _network_loop_retry
    if not await action_cb():
  File "/home/hokenz/.local/lib/python3.10/site-packages/telegram/ext/_updater.py", line 345, in polling_action_cb
    raise exc
  File "/home/hokenz/.local/lib/python3.10/site-packages/telegram/ext/_updater.py", line 334, in polling_action_cb
    updates = await self.bot.get_updates(
  File "/home/hokenz/.local/lib/python3.10/site-packages/telegram/ext/_extbot.py", line 565, in get_updates
    updates = await super().get_updates(
  File "/home/hokenz/.local/lib/python3.10/site-packages/telegram/_bot.py", line 519, in decorator
    result = await func(self, *args, **kwargs)  # skipcq: PYL-E1102
  File "/home/hokenz/.local/lib/python3.10/site-packages/telegram/_bot.py", line 3562, in get_updates
    await self._post(
  File "/home/hokenz/.local/lib/python3.10/site-packages/telegram/_bot.py", line 607, in _post
    return await self._do_post(
  File "/home/hokenz/.local/lib/python3.10/site-packages/telegram/ext/_extbot.py", line 347, in _do_post
    return await super()._do_post(
  File "/home/hokenz/.local/lib/python3.10/site-packages/telegram/_bot.py", line 635, in _do_post
    return await request.post(
  File "/home/hokenz/.local/lib/python3.10/site-packages/telegram/request/_baserequest.py", line 168, in post
    result = await self._request_wrapper(
  File "/home/hokenz/.local/lib/python3.10/site-packages/telegram/request/_baserequest.py", line 288, in _request_wrapper
    raise exc
  File "/home/hokenz/.local/lib/python3.10/site-packages/telegram/request/_baserequest.py", line 278, in _request_wrapper
    code, payload = await self.do_request(
  File "/home/hokenz/.local/lib/python3.10/site-packages/telegram/request/_httpxrequest.py", line 243, in do_request
    raise NetworkError(f"httpx.{err.__class__.__name__}: {err}") from err
telegram.error.NetworkError: httpx.ReadError: 
Error while getting Updates: httpx.ReadError: 
No error handlers are registered, logging exception.
Traceback (most recent call last):
  File "/home/hokenz/.local/lib/python3.10/site-packages/httpcore/_exceptions.py", line 10, in map_exceptions
    yield
  File "/home/hokenz/.local/lib/python3.10/site-packages/httpcore/_backends/anyio.py", line 34, in read
    return await self._stream.receive(max_bytes=max_bytes)
  File "/home/hokenz/.local/lib/python3.10/site-packages/anyio/streams/tls.py", line 198, in receive
    data = await self._call_sslobject_method(self._ssl_object.read, max_bytes)
  File "/home/hokenz/.local/lib/python3.10/site-packages/anyio/streams/tls.py", line 140, in _call_sslobject_method
    data = await self.transport_stream.receive()
  File "/home/hokenz/.local/lib/python3.10/site-packages/anyio/_backends/_asyncio.py", line 1104, in receive
    raise self._protocol.exception from None
anyio.BrokenResourceError

The above exception was the direct cause of the following exception:

Traceback (most recent call last):
  File "/home/hokenz/.local/lib/python3.10/site-packages/httpx/_transports/default.py", line 66, in map_httpcore_exceptions
    yield
  File "/home/hokenz/.local/lib/python3.10/site-packages/httpx/_transports/default.py", line 366, in handle_async_request
    resp = await self._pool.handle_async_request(req)
  File "/home/hokenz/.local/lib/python3.10/site-packages/httpcore/_async/connection_pool.py", line 268, in handle_async_request
    raise exc
  File "/home/hokenz/.local/lib/python3.10/site-packages/httpcore/_async/connection_pool.py", line 251, in handle_async_request
    response = await connection.handle_async_request(request)
  File "/home/hokenz/.local/lib/python3.10/site-packages/httpcore/_async/connection.py", line 103, in handle_async_request
    return await self._connection.handle_async_request(request)
  File "/home/hokenz/.local/lib/python3.10/site-packages/httpcore/_async/http11.py", line 133, in handle_async_request
    raise exc
  File "/home/hokenz/.local/lib/python3.10/site-packages/httpcore/_async/http11.py", line 111, in handle_async_request
    ) = await self._receive_response_headers(**kwargs)
  File "/home/hokenz/.local/lib/python3.10/site-packages/httpcore/_async/http11.py", line 176, in _receive_response_headers
    event = await self._receive_event(timeout=timeout)
  File "/home/hokenz/.local/lib/python3.10/site-packages/httpcore/_async/http11.py", line 212, in _receive_event
    data = await self._network_stream.read(
  File "/home/hokenz/.local/lib/python3.10/site-packages/httpcore/_backends/anyio.py", line 31, in read
    with map_exceptions(exc_map):
  File "/usr/lib/python3.10/contextlib.py", line 153, in __exit__
    self.gen.throw(typ, value, traceback)
  File "/home/hokenz/.local/lib/python3.10/site-packages/httpcore/_exceptions.py", line 14, in map_exceptions
    raise to_exc(exc) from exc
httpcore.ReadError

The above exception was the direct cause of the following exception:

Traceback (most recent call last):
  File "/home/hokenz/.local/lib/python3.10/site-packages/telegram/request/_httpxrequest.py", line 219, in do_request
    res = await self._client.request(
  File "/home/hokenz/.local/lib/python3.10/site-packages/httpx/_client.py", line 1530, in request
    return await self.send(request, auth=auth, follow_redirects=follow_redirects)
  File "/home/hokenz/.local/lib/python3.10/site-packages/httpx/_client.py", line 1617, in send
    response = await self._send_handling_auth(
  File "/home/hokenz/.local/lib/python3.10/site-packages/httpx/_client.py", line 1645, in _send_handling_auth
    response = await self._send_handling_redirects(
  File "/home/hokenz/.local/lib/python3.10/site-packages/httpx/_client.py", line 1682, in _send_handling_redirects
    response = await self._send_single_request(request)
  File "/home/hokenz/.local/lib/python3.10/site-packages/httpx/_client.py", line 1719, in _send_single_request
    response = await transport.handle_async_request(request)
  File "/home/hokenz/.local/lib/python3.10/site-packages/httpx/_transports/default.py", line 365, in handle_async_request
    with map_httpcore_exceptions():
  File "/usr/lib/python3.10/contextlib.py", line 153, in __exit__
    self.gen.throw(typ, value, traceback)
  File "/home/hokenz/.local/lib/python3.10/site-packages/httpx/_transports/default.py", line 83, in map_httpcore_exceptions
    raise mapped_exc(message) from exc
httpx.ReadError

The above exception was the direct cause of the following exception:

Traceback (most recent call last):
  File "/home/hokenz/.local/lib/python3.10/site-packages/telegram/ext/_updater.py", line 640, in _network_loop_retry
    if not await action_cb():
  File "/home/hokenz/.local/lib/python3.10/site-packages/telegram/ext/_updater.py", line 345, in polling_action_cb
    raise exc
  File "/home/hokenz/.local/lib/python3.10/site-packages/telegram/ext/_updater.py", line 334, in polling_action_cb
    updates = await self.bot.get_updates(
  File "/home/hokenz/.local/lib/python3.10/site-packages/telegram/ext/_extbot.py", line 565, in get_updates
    updates = await super().get_updates(
  File "/home/hokenz/.local/lib/python3.10/site-packages/telegram/_bot.py", line 519, in decorator
    result = await func(self, *args, **kwargs)  # skipcq: PYL-E1102
  File "/home/hokenz/.local/lib/python3.10/site-packages/telegram/_bot.py", line 3562, in get_updates
    await self._post(
  File "/home/hokenz/.local/lib/python3.10/site-packages/telegram/_bot.py", line 607, in _post
    return await self._do_post(
  File "/home/hokenz/.local/lib/python3.10/site-packages/telegram/ext/_extbot.py", line 347, in _do_post
    return await super()._do_post(
  File "/home/hokenz/.local/lib/python3.10/site-packages/telegram/_bot.py", line 635, in _do_post
    return await request.post(
  File "/home/hokenz/.local/lib/python3.10/site-packages/telegram/request/_baserequest.py", line 168, in post
    result = await self._request_wrapper(
  File "/home/hokenz/.local/lib/python3.10/site-packages/telegram/request/_baserequest.py", line 288, in _request_wrapper
    raise exc
  File "/home/hokenz/.local/lib/python3.10/site-packages/telegram/request/_baserequest.py", line 278, in _request_wrapper
    code, payload = await self.do_request(
  File "/home/hokenz/.local/lib/python3.10/site-packages/telegram/request/_httpxrequest.py", line 243, in do_request
    raise NetworkError(f"httpx.{err.__class__.__name__}: {err}") from err
telegram.error.NetworkError: httpx.ReadError: 
Error while getting Updates: httpx.ReadError: 
No error handlers are registered, logging exception.
Traceback (most recent call last):
  File "/home/hokenz/.local/lib/python3.10/site-packages/httpcore/_exceptions.py", line 10, in map_exceptions
    yield
  File "/home/hokenz/.local/lib/python3.10/site-packages/httpcore/_backends/anyio.py", line 34, in read
    return await self._stream.receive(max_bytes=max_bytes)
  File "/home/hokenz/.local/lib/python3.10/site-packages/anyio/streams/tls.py", line 198, in receive
    data = await self._call_sslobject_method(self._ssl_object.read, max_bytes)
  File "/home/hokenz/.local/lib/python3.10/site-packages/anyio/streams/tls.py", line 140, in _call_sslobject_method
    data = await self.transport_stream.receive()
  File "/home/hokenz/.local/lib/python3.10/site-packages/anyio/_backends/_asyncio.py", line 1104, in receive
    raise self._protocol.exception from None
anyio.BrokenResourceError

The above exception was the direct cause of the following exception:

Traceback (most recent call last):
  File "/home/hokenz/.local/lib/python3.10/site-packages/httpx/_transports/default.py", line 66, in map_httpcore_exceptions
    yield
  File "/home/hokenz/.local/lib/python3.10/site-packages/httpx/_transports/default.py", line 366, in handle_async_request
    resp = await self._pool.handle_async_request(req)
  File "/home/hokenz/.local/lib/python3.10/site-packages/httpcore/_async/connection_pool.py", line 268, in handle_async_request
    raise exc
  File "/home/hokenz/.local/lib/python3.10/site-packages/httpcore/_async/connection_pool.py", line 251, in handle_async_request
    response = await connection.handle_async_request(request)
  File "/home/hokenz/.local/lib/python3.10/site-packages/httpcore/_async/connection.py", line 103, in handle_async_request
    return await self._connection.handle_async_request(request)
  File "/home/hokenz/.local/lib/python3.10/site-packages/httpcore/_async/http11.py", line 133, in handle_async_request
    raise exc
  File "/home/hokenz/.local/lib/python3.10/site-packages/httpcore/_async/http11.py", line 111, in handle_async_request
    ) = await self._receive_response_headers(**kwargs)
  File "/home/hokenz/.local/lib/python3.10/site-packages/httpcore/_async/http11.py", line 176, in _receive_response_headers
    event = await self._receive_event(timeout=timeout)
  File "/home/hokenz/.local/lib/python3.10/site-packages/httpcore/_async/http11.py", line 212, in _receive_event
    data = await self._network_stream.read(
  File "/home/hokenz/.local/lib/python3.10/site-packages/httpcore/_backends/anyio.py", line 31, in read
    with map_exceptions(exc_map):
  File "/usr/lib/python3.10/contextlib.py", line 153, in __exit__
    self.gen.throw(typ, value, traceback)
  File "/home/hokenz/.local/lib/python3.10/site-packages/httpcore/_exceptions.py", line 14, in map_exceptions
    raise to_exc(exc) from exc
httpcore.ReadError

The above exception was the direct cause of the following exception:

Traceback (most recent call last):
  File "/home/hokenz/.local/lib/python3.10/site-packages/telegram/request/_httpxrequest.py", line 219, in do_request
    res = await self._client.request(
  File "/home/hokenz/.local/lib/python3.10/site-packages/httpx/_client.py", line 1530, in request
    return await self.send(request, auth=auth, follow_redirects=follow_redirects)
  File "/home/hokenz/.local/lib/python3.10/site-packages/httpx/_client.py", line 1617, in send
    response = await self._send_handling_auth(
  File "/home/hokenz/.local/lib/python3.10/site-packages/httpx/_client.py", line 1645, in _send_handling_auth
    response = await self._send_handling_redirects(
  File "/home/hokenz/.local/lib/python3.10/site-packages/httpx/_client.py", line 1682, in _send_handling_redirects
    response = await self._send_single_request(request)
  File "/home/hokenz/.local/lib/python3.10/site-packages/httpx/_client.py", line 1719, in _send_single_request
    response = await transport.handle_async_request(request)
  File "/home/hokenz/.local/lib/python3.10/site-packages/httpx/_transports/default.py", line 365, in handle_async_request
    with map_httpcore_exceptions():
  File "/usr/lib/python3.10/contextlib.py", line 153, in __exit__
    self.gen.throw(typ, value, traceback)
  File "/home/hokenz/.local/lib/python3.10/site-packages/httpx/_transports/default.py", line 83, in map_httpcore_exceptions
    raise mapped_exc(message) from exc
httpx.ReadError

The above exception was the direct cause of the following exception:

Traceback (most recent call last):
  File "/home/hokenz/.local/lib/python3.10/site-packages/telegram/ext/_updater.py", line 640, in _network_loop_retry
    if not await action_cb():
  File "/home/hokenz/.local/lib/python3.10/site-packages/telegram/ext/_updater.py", line 345, in polling_action_cb
    raise exc
  File "/home/hokenz/.local/lib/python3.10/site-packages/telegram/ext/_updater.py", line 334, in polling_action_cb
    updates = await self.bot.get_updates(
  File "/home/hokenz/.local/lib/python3.10/site-packages/telegram/ext/_extbot.py", line 565, in get_updates
    updates = await super().get_updates(
  File "/home/hokenz/.local/lib/python3.10/site-packages/telegram/_bot.py", line 519, in decorator
    result = await func(self, *args, **kwargs)  # skipcq: PYL-E1102
  File "/home/hokenz/.local/lib/python3.10/site-packages/telegram/_bot.py", line 3562, in get_updates
    await self._post(
  File "/home/hokenz/.local/lib/python3.10/site-packages/telegram/_bot.py", line 607, in _post
    return await self._do_post(
  File "/home/hokenz/.local/lib/python3.10/site-packages/telegram/ext/_extbot.py", line 347, in _do_post
    return await super()._do_post(
  File "/home/hokenz/.local/lib/python3.10/site-packages/telegram/_bot.py", line 635, in _do_post
    return await request.post(
  File "/home/hokenz/.local/lib/python3.10/site-packages/telegram/request/_baserequest.py", line 168, in post
    result = await self._request_wrapper(
  File "/home/hokenz/.local/lib/python3.10/site-packages/telegram/request/_baserequest.py", line 288, in _request_wrapper
    raise exc
  File "/home/hokenz/.local/lib/python3.10/site-packages/telegram/request/_baserequest.py", line 278, in _request_wrapper
    code, payload = await self.do_request(
  File "/home/hokenz/.local/lib/python3.10/site-packages/telegram/request/_httpxrequest.py", line 243, in do_request
    raise NetworkError(f"httpx.{err.__class__.__name__}: {err}") from err
telegram.error.NetworkError: httpx.ReadError: 
No error handlers are registered, logging exception.
Traceback (most recent call last):
  File "/home/hokenz/.local/lib/python3.10/site-packages/telegram/ext/_application.py", line 1195, in process_update
    await coroutine
  File "/home/hokenz/.local/lib/python3.10/site-packages/telegram/ext/_basehandler.py", line 153, in handle_update
    return await self.callback(update, context)
  File "/home/hokenz/Desktop/schedulebot/pybot.py", line 19, in button
    await query.message.reply_text(text=schedule.get_schedule(query.data), reply_markup=reply_markup)
  File "/home/hokenz/Desktop/schedulebot/schedule.py", line 37, in get_schedule
    response = session.get(url, headers=headers).json()
  File "/usr/lib/python3/dist-packages/requests/models.py", line 900, in json
    return complexjson.loads(self.text, **kwargs)
  File "/usr/lib/python3.10/json/__init__.py", line 346, in loads
    return _default_decoder.decode(s)
  File "/usr/lib/python3.10/json/decoder.py", line 337, in decode
    obj, end = self.raw_decode(s, idx=_w(s, 0).end())
  File "/usr/lib/python3.10/json/decoder.py", line 355, in raw_decode
    raise JSONDecodeError("Expecting value", s, err.value) from None
json.decoder.JSONDecodeError: Expecting value: line 1 column 1 (char 0)
Error while getting Updates: httpx.ReadError: 
No error handlers are registered, logging exception.
Traceback (most recent call last):
  File "/home/hokenz/.local/lib/python3.10/site-packages/httpcore/_exceptions.py", line 10, in map_exceptions
    yield
  File "/home/hokenz/.local/lib/python3.10/site-packages/httpcore/_backends/anyio.py", line 34, in read
    return await self._stream.receive(max_bytes=max_bytes)
  File "/home/hokenz/.local/lib/python3.10/site-packages/anyio/streams/tls.py", line 198, in receive
    data = await self._call_sslobject_method(self._ssl_object.read, max_bytes)
  File "/home/hokenz/.local/lib/python3.10/site-packages/anyio/streams/tls.py", line 140, in _call_sslobject_method
    data = await self.transport_stream.receive()
  File "/home/hokenz/.local/lib/python3.10/site-packages/anyio/_backends/_asyncio.py", line 1104, in receive
    raise self._protocol.exception from None
anyio.BrokenResourceError

The above exception was the direct cause of the following exception:

Traceback (most recent call last):
  File "/home/hokenz/.local/lib/python3.10/site-packages/httpx/_transports/default.py", line 66, in map_httpcore_exceptions
    yield
  File "/home/hokenz/.local/lib/python3.10/site-packages/httpx/_transports/default.py", line 366, in handle_async_request
    resp = await self._pool.handle_async_request(req)
  File "/home/hokenz/.local/lib/python3.10/site-packages/httpcore/_async/connection_pool.py", line 268, in handle_async_request
    raise exc
  File "/home/hokenz/.local/lib/python3.10/site-packages/httpcore/_async/connection_pool.py", line 251, in handle_async_request
    response = await connection.handle_async_request(request)
  File "/home/hokenz/.local/lib/python3.10/site-packages/httpcore/_async/connection.py", line 103, in handle_async_request
    return await self._connection.handle_async_request(request)
  File "/home/hokenz/.local/lib/python3.10/site-packages/httpcore/_async/http11.py", line 133, in handle_async_request
    raise exc
  File "/home/hokenz/.local/lib/python3.10/site-packages/httpcore/_async/http11.py", line 111, in handle_async_request
    ) = await self._receive_response_headers(**kwargs)
  File "/home/hokenz/.local/lib/python3.10/site-packages/httpcore/_async/http11.py", line 176, in _receive_response_headers
    event = await self._receive_event(timeout=timeout)
  File "/home/hokenz/.local/lib/python3.10/site-packages/httpcore/_async/http11.py", line 212, in _receive_event
    data = await self._network_stream.read(
  File "/home/hokenz/.local/lib/python3.10/site-packages/httpcore/_backends/anyio.py", line 31, in read
    with map_exceptions(exc_map):
  File "/usr/lib/python3.10/contextlib.py", line 153, in __exit__
    self.gen.throw(typ, value, traceback)
  File "/home/hokenz/.local/lib/python3.10/site-packages/httpcore/_exceptions.py", line 14, in map_exceptions
    raise to_exc(exc) from exc
httpcore.ReadError

The above exception was the direct cause of the following exception:

Traceback (most recent call last):
  File "/home/hokenz/.local/lib/python3.10/site-packages/telegram/request/_httpxrequest.py", line 219, in do_request
    res = await self._client.request(
  File "/home/hokenz/.local/lib/python3.10/site-packages/httpx/_client.py", line 1530, in request
    return await self.send(request, auth=auth, follow_redirects=follow_redirects)
  File "/home/hokenz/.local/lib/python3.10/site-packages/httpx/_client.py", line 1617, in send
    response = await self._send_handling_auth(
  File "/home/hokenz/.local/lib/python3.10/site-packages/httpx/_client.py", line 1645, in _send_handling_auth
    response = await self._send_handling_redirects(
  File "/home/hokenz/.local/lib/python3.10/site-packages/httpx/_client.py", line 1682, in _send_handling_redirects
    response = await self._send_single_request(request)
  File "/home/hokenz/.local/lib/python3.10/site-packages/httpx/_client.py", line 1719, in _send_single_request
    response = await transport.handle_async_request(request)
  File "/home/hokenz/.local/lib/python3.10/site-packages/httpx/_transports/default.py", line 365, in handle_async_request
    with map_httpcore_exceptions():
  File "/usr/lib/python3.10/contextlib.py", line 153, in __exit__
    self.gen.throw(typ, value, traceback)
  File "/home/hokenz/.local/lib/python3.10/site-packages/httpx/_transports/default.py", line 83, in map_httpcore_exceptions
    raise mapped_exc(message) from exc
httpx.ReadError

The above exception was the direct cause of the following exception:

Traceback (most recent call last):
  File "/home/hokenz/.local/lib/python3.10/site-packages/telegram/ext/_updater.py", line 640, in _network_loop_retry
    if not await action_cb():
  File "/home/hokenz/.local/lib/python3.10/site-packages/telegram/ext/_updater.py", line 345, in polling_action_cb
    raise exc
  File "/home/hokenz/.local/lib/python3.10/site-packages/telegram/ext/_updater.py", line 334, in polling_action_cb
    updates = await self.bot.get_updates(
  File "/home/hokenz/.local/lib/python3.10/site-packages/telegram/ext/_extbot.py", line 565, in get_updates
    updates = await super().get_updates(
  File "/home/hokenz/.local/lib/python3.10/site-packages/telegram/_bot.py", line 519, in decorator
    result = await func(self, *args, **kwargs)  # skipcq: PYL-E1102
  File "/home/hokenz/.local/lib/python3.10/site-packages/telegram/_bot.py", line 3562, in get_updates
    await self._post(
  File "/home/hokenz/.local/lib/python3.10/site-packages/telegram/_bot.py", line 607, in _post
    return await self._do_post(
  File "/home/hokenz/.local/lib/python3.10/site-packages/telegram/ext/_extbot.py", line 347, in _do_post
    return await super()._do_post(
  File "/home/hokenz/.local/lib/python3.10/site-packages/telegram/_bot.py", line 635, in _do_post
    return await request.post(
  File "/home/hokenz/.local/lib/python3.10/site-packages/telegram/request/_baserequest.py", line 168, in post
    result = await self._request_wrapper(
  File "/home/hokenz/.local/lib/python3.10/site-packages/telegram/request/_baserequest.py", line 288, in _request_wrapper
    raise exc
  File "/home/hokenz/.local/lib/python3.10/site-packages/telegram/request/_baserequest.py", line 278, in _request_wrapper
    code, payload = await self.do_request(
  File "/home/hokenz/.local/lib/python3.10/site-packages/telegram/request/_httpxrequest.py", line 243, in do_request
    raise NetworkError(f"httpx.{err.__class__.__name__}: {err}") from err
telegram.error.NetworkError: httpx.ReadError: 
Error while getting Updates: httpx.ReadError: 
No error handlers are registered, logging exception.
Traceback (most recent call last):
  File "/home/hokenz/.local/lib/python3.10/site-packages/httpcore/_exceptions.py", line 10, in map_exceptions
    yield
  File "/home/hokenz/.local/lib/python3.10/site-packages/httpcore/_backends/anyio.py", line 34, in read
    return await self._stream.receive(max_bytes=max_bytes)
  File "/home/hokenz/.local/lib/python3.10/site-packages/anyio/streams/tls.py", line 198, in receive
    data = await self._call_sslobject_method(self._ssl_object.read, max_bytes)
  File "/home/hokenz/.local/lib/python3.10/site-packages/anyio/streams/tls.py", line 140, in _call_sslobject_method
    data = await self.transport_stream.receive()
  File "/home/hokenz/.local/lib/python3.10/site-packages/anyio/_backends/_asyncio.py", line 1104, in receive
    raise self._protocol.exception from None
anyio.BrokenResourceError

The above exception was the direct cause of the following exception:

Traceback (most recent call last):
  File "/home/hokenz/.local/lib/python3.10/site-packages/httpx/_transports/default.py", line 66, in map_httpcore_exceptions
    yield
  File "/home/hokenz/.local/lib/python3.10/site-packages/httpx/_transports/default.py", line 366, in handle_async_request
    resp = await self._pool.handle_async_request(req)
  File "/home/hokenz/.local/lib/python3.10/site-packages/httpcore/_async/connection_pool.py", line 268, in handle_async_request
    raise exc
  File "/home/hokenz/.local/lib/python3.10/site-packages/httpcore/_async/connection_pool.py", line 251, in handle_async_request
    response = await connection.handle_async_request(request)
  File "/home/hokenz/.local/lib/python3.10/site-packages/httpcore/_async/connection.py", line 103, in handle_async_request
    return await self._connection.handle_async_request(request)
  File "/home/hokenz/.local/lib/python3.10/site-packages/httpcore/_async/http11.py", line 133, in handle_async_request
    raise exc
  File "/home/hokenz/.local/lib/python3.10/site-packages/httpcore/_async/http11.py", line 111, in handle_async_request
    ) = await self._receive_response_headers(**kwargs)
  File "/home/hokenz/.local/lib/python3.10/site-packages/httpcore/_async/http11.py", line 176, in _receive_response_headers
    event = await self._receive_event(timeout=timeout)
  File "/home/hokenz/.local/lib/python3.10/site-packages/httpcore/_async/http11.py", line 212, in _receive_event
    data = await self._network_stream.read(
  File "/home/hokenz/.local/lib/python3.10/site-packages/httpcore/_backends/anyio.py", line 31, in read
    with map_exceptions(exc_map):
  File "/usr/lib/python3.10/contextlib.py", line 153, in __exit__
    self.gen.throw(typ, value, traceback)
  File "/home/hokenz/.local/lib/python3.10/site-packages/httpcore/_exceptions.py", line 14, in map_exceptions
    raise to_exc(exc) from exc
httpcore.ReadError

The above exception was the direct cause of the following exception:

Traceback (most recent call last):
  File "/home/hokenz/.local/lib/python3.10/site-packages/telegram/request/_httpxrequest.py", line 219, in do_request
    res = await self._client.request(
  File "/home/hokenz/.local/lib/python3.10/site-packages/httpx/_client.py", line 1530, in request
    return await self.send(request, auth=auth, follow_redirects=follow_redirects)
  File "/home/hokenz/.local/lib/python3.10/site-packages/httpx/_client.py", line 1617, in send
    response = await self._send_handling_auth(
  File "/home/hokenz/.local/lib/python3.10/site-packages/httpx/_client.py", line 1645, in _send_handling_auth
    response = await self._send_handling_redirects(
  File "/home/hokenz/.local/lib/python3.10/site-packages/httpx/_client.py", line 1682, in _send_handling_redirects
    response = await self._send_single_request(request)
  File "/home/hokenz/.local/lib/python3.10/site-packages/httpx/_client.py", line 1719, in _send_single_request
    response = await transport.handle_async_request(request)
  File "/home/hokenz/.local/lib/python3.10/site-packages/httpx/_transports/default.py", line 365, in handle_async_request
    with map_httpcore_exceptions():
  File "/usr/lib/python3.10/contextlib.py", line 153, in __exit__
    self.gen.throw(typ, value, traceback)
  File "/home/hokenz/.local/lib/python3.10/site-packages/httpx/_transports/default.py", line 83, in map_httpcore_exceptions
    raise mapped_exc(message) from exc
httpx.ReadError

The above exception was the direct cause of the following exception:

Traceback (most recent call last):
  File "/home/hokenz/.local/lib/python3.10/site-packages/telegram/ext/_updater.py", line 640, in _network_loop_retry
    if not await action_cb():
  File "/home/hokenz/.local/lib/python3.10/site-packages/telegram/ext/_updater.py", line 345, in polling_action_cb
    raise exc
  File "/home/hokenz/.local/lib/python3.10/site-packages/telegram/ext/_updater.py", line 334, in polling_action_cb
    updates = await self.bot.get_updates(
  File "/home/hokenz/.local/lib/python3.10/site-packages/telegram/ext/_extbot.py", line 565, in get_updates
    updates = await super().get_updates(
  File "/home/hokenz/.local/lib/python3.10/site-packages/telegram/_bot.py", line 519, in decorator
    result = await func(self, *args, **kwargs)  # skipcq: PYL-E1102
  File "/home/hokenz/.local/lib/python3.10/site-packages/telegram/_bot.py", line 3562, in get_updates
    await self._post(
  File "/home/hokenz/.local/lib/python3.10/site-packages/telegram/_bot.py", line 607, in _post
    return await self._do_post(
  File "/home/hokenz/.local/lib/python3.10/site-packages/telegram/ext/_extbot.py", line 347, in _do_post
    return await super()._do_post(
  File "/home/hokenz/.local/lib/python3.10/site-packages/telegram/_bot.py", line 635, in _do_post
    return await request.post(
  File "/home/hokenz/.local/lib/python3.10/site-packages/telegram/request/_baserequest.py", line 168, in post
    result = await self._request_wrapper(
  File "/home/hokenz/.local/lib/python3.10/site-packages/telegram/request/_baserequest.py", line 288, in _request_wrapper
    raise exc
  File "/home/hokenz/.local/lib/python3.10/site-packages/telegram/request/_baserequest.py", line 278, in _request_wrapper
    code, payload = await self.do_request(
  File "/home/hokenz/.local/lib/python3.10/site-packages/telegram/request/_httpxrequest.py", line 243, in do_request
    raise NetworkError(f"httpx.{err.__class__.__name__}: {err}") from err
telegram.error.NetworkError: httpx.ReadError: 
Error while getting Updates: httpx.ReadError: 
No error handlers are registered, logging exception.
Traceback (most recent call last):
  File "/home/hokenz/.local/lib/python3.10/site-packages/httpcore/_exceptions.py", line 10, in map_exceptions
    yield
  File "/home/hokenz/.local/lib/python3.10/site-packages/httpcore/_backends/anyio.py", line 34, in read
    return await self._stream.receive(max_bytes=max_bytes)
  File "/home/hokenz/.local/lib/python3.10/site-packages/anyio/streams/tls.py", line 198, in receive
    data = await self._call_sslobject_method(self._ssl_object.read, max_bytes)
  File "/home/hokenz/.local/lib/python3.10/site-packages/anyio/streams/tls.py", line 140, in _call_sslobject_method
    data = await self.transport_stream.receive()
  File "/home/hokenz/.local/lib/python3.10/site-packages/anyio/_backends/_asyncio.py", line 1104, in receive
    raise self._protocol.exception from None
anyio.BrokenResourceError

The above exception was the direct cause of the following exception:

Traceback (most recent call last):
  File "/home/hokenz/.local/lib/python3.10/site-packages/httpx/_transports/default.py", line 66, in map_httpcore_exceptions
    yield
  File "/home/hokenz/.local/lib/python3.10/site-packages/httpx/_transports/default.py", line 366, in handle_async_request
    resp = await self._pool.handle_async_request(req)
  File "/home/hokenz/.local/lib/python3.10/site-packages/httpcore/_async/connection_pool.py", line 268, in handle_async_request
    raise exc
  File "/home/hokenz/.local/lib/python3.10/site-packages/httpcore/_async/connection_pool.py", line 251, in handle_async_request
    response = await connection.handle_async_request(request)
  File "/home/hokenz/.local/lib/python3.10/site-packages/httpcore/_async/connection.py", line 103, in handle_async_request
    return await self._connection.handle_async_request(request)
  File "/home/hokenz/.local/lib/python3.10/site-packages/httpcore/_async/http11.py", line 133, in handle_async_request
    raise exc
  File "/home/hokenz/.local/lib/python3.10/site-packages/httpcore/_async/http11.py", line 111, in handle_async_request
    ) = await self._receive_response_headers(**kwargs)
  File "/home/hokenz/.local/lib/python3.10/site-packages/httpcore/_async/http11.py", line 176, in _receive_response_headers
    event = await self._receive_event(timeout=timeout)
  File "/home/hokenz/.local/lib/python3.10/site-packages/httpcore/_async/http11.py", line 212, in _receive_event
    data = await self._network_stream.read(
  File "/home/hokenz/.local/lib/python3.10/site-packages/httpcore/_backends/anyio.py", line 31, in read
    with map_exceptions(exc_map):
  File "/usr/lib/python3.10/contextlib.py", line 153, in __exit__
    self.gen.throw(typ, value, traceback)
  File "/home/hokenz/.local/lib/python3.10/site-packages/httpcore/_exceptions.py", line 14, in map_exceptions
    raise to_exc(exc) from exc
httpcore.ReadError

The above exception was the direct cause of the following exception:

Traceback (most recent call last):
  File "/home/hokenz/.local/lib/python3.10/site-packages/telegram/request/_httpxrequest.py", line 219, in do_request
    res = await self._client.request(
  File "/home/hokenz/.local/lib/python3.10/site-packages/httpx/_client.py", line 1530, in request
    return await self.send(request, auth=auth, follow_redirects=follow_redirects)
  File "/home/hokenz/.local/lib/python3.10/site-packages/httpx/_client.py", line 1617, in send
    response = await self._send_handling_auth(
  File "/home/hokenz/.local/lib/python3.10/site-packages/httpx/_client.py", line 1645, in _send_handling_auth
    response = await self._send_handling_redirects(
  File "/home/hokenz/.local/lib/python3.10/site-packages/httpx/_client.py", line 1682, in _send_handling_redirects
    response = await self._send_single_request(request)
  File "/home/hokenz/.local/lib/python3.10/site-packages/httpx/_client.py", line 1719, in _send_single_request
    response = await transport.handle_async_request(request)
  File "/home/hokenz/.local/lib/python3.10/site-packages/httpx/_transports/default.py", line 365, in handle_async_request
    with map_httpcore_exceptions():
  File "/usr/lib/python3.10/contextlib.py", line 153, in __exit__
    self.gen.throw(typ, value, traceback)
  File "/home/hokenz/.local/lib/python3.10/site-packages/httpx/_transports/default.py", line 83, in map_httpcore_exceptions
    raise mapped_exc(message) from exc
httpx.ReadError

The above exception was the direct cause of the following exception:

Traceback (most recent call last):
  File "/home/hokenz/.local/lib/python3.10/site-packages/telegram/ext/_updater.py", line 640, in _network_loop_retry
    if not await action_cb():
  File "/home/hokenz/.local/lib/python3.10/site-packages/telegram/ext/_updater.py", line 345, in polling_action_cb
    raise exc
  File "/home/hokenz/.local/lib/python3.10/site-packages/telegram/ext/_updater.py", line 334, in polling_action_cb
    updates = await self.bot.get_updates(
  File "/home/hokenz/.local/lib/python3.10/site-packages/telegram/ext/_extbot.py", line 565, in get_updates
    updates = await super().get_updates(
  File "/home/hokenz/.local/lib/python3.10/site-packages/telegram/_bot.py", line 519, in decorator
    result = await func(self, *args, **kwargs)  # skipcq: PYL-E1102
  File "/home/hokenz/.local/lib/python3.10/site-packages/telegram/_bot.py", line 3562, in get_updates
    await self._post(
  File "/home/hokenz/.local/lib/python3.10/site-packages/telegram/_bot.py", line 607, in _post
    return await self._do_post(
  File "/home/hokenz/.local/lib/python3.10/site-packages/telegram/ext/_extbot.py", line 347, in _do_post
    return await super()._do_post(
  File "/home/hokenz/.local/lib/python3.10/site-packages/telegram/_bot.py", line 635, in _do_post
    return await request.post(
  File "/home/hokenz/.local/lib/python3.10/site-packages/telegram/request/_baserequest.py", line 168, in post
    result = await self._request_wrapper(
  File "/home/hokenz/.local/lib/python3.10/site-packages/telegram/request/_baserequest.py", line 288, in _request_wrapper
    raise exc
  File "/home/hokenz/.local/lib/python3.10/site-packages/telegram/request/_baserequest.py", line 278, in _request_wrapper
    code, payload = await self.do_request(
  File "/home/hokenz/.local/lib/python3.10/site-packages/telegram/request/_httpxrequest.py", line 243, in do_request
    raise NetworkError(f"httpx.{err.__class__.__name__}: {err}") from err
telegram.error.NetworkError: httpx.ReadError: 
Error while getting Updates: httpx.ReadError: 
No error handlers are registered, logging exception.
Traceback (most recent call last):
  File "/home/hokenz/.local/lib/python3.10/site-packages/httpcore/_exceptions.py", line 10, in map_exceptions
    yield
  File "/home/hokenz/.local/lib/python3.10/site-packages/httpcore/_backends/anyio.py", line 34, in read
    return await self._stream.receive(max_bytes=max_bytes)
  File "/home/hokenz/.local/lib/python3.10/site-packages/anyio/streams/tls.py", line 198, in receive
    data = await self._call_sslobject_method(self._ssl_object.read, max_bytes)
  File "/home/hokenz/.local/lib/python3.10/site-packages/anyio/streams/tls.py", line 140, in _call_sslobject_method
    data = await self.transport_stream.receive()
  File "/home/hokenz/.local/lib/python3.10/site-packages/anyio/_backends/_asyncio.py", line 1104, in receive
    raise self._protocol.exception from None
anyio.BrokenResourceError

The above exception was the direct cause of the following exception:

Traceback (most recent call last):
  File "/home/hokenz/.local/lib/python3.10/site-packages/httpx/_transports/default.py", line 66, in map_httpcore_exceptions
    yield
  File "/home/hokenz/.local/lib/python3.10/site-packages/httpx/_transports/default.py", line 366, in handle_async_request
    resp = await self._pool.handle_async_request(req)
  File "/home/hokenz/.local/lib/python3.10/site-packages/httpcore/_async/connection_pool.py", line 268, in handle_async_request
    raise exc
  File "/home/hokenz/.local/lib/python3.10/site-packages/httpcore/_async/connection_pool.py", line 251, in handle_async_request
    response = await connection.handle_async_request(request)
  File "/home/hokenz/.local/lib/python3.10/site-packages/httpcore/_async/connection.py", line 103, in handle_async_request
    return await self._connection.handle_async_request(request)
  File "/home/hokenz/.local/lib/python3.10/site-packages/httpcore/_async/http11.py", line 133, in handle_async_request
    raise exc
  File "/home/hokenz/.local/lib/python3.10/site-packages/httpcore/_async/http11.py", line 111, in handle_async_request
    ) = await self._receive_response_headers(**kwargs)
  File "/home/hokenz/.local/lib/python3.10/site-packages/httpcore/_async/http11.py", line 176, in _receive_response_headers
    event = await self._receive_event(timeout=timeout)
  File "/home/hokenz/.local/lib/python3.10/site-packages/httpcore/_async/http11.py", line 212, in _receive_event
    data = await self._network_stream.read(
  File "/home/hokenz/.local/lib/python3.10/site-packages/httpcore/_backends/anyio.py", line 31, in read
    with map_exceptions(exc_map):
  File "/usr/lib/python3.10/contextlib.py", line 153, in __exit__
    self.gen.throw(typ, value, traceback)
  File "/home/hokenz/.local/lib/python3.10/site-packages/httpcore/_exceptions.py", line 14, in map_exceptions
    raise to_exc(exc) from exc
httpcore.ReadError

The above exception was the direct cause of the following exception:

Traceback (most recent call last):
  File "/home/hokenz/.local/lib/python3.10/site-packages/telegram/request/_httpxrequest.py", line 219, in do_request
    res = await self._client.request(
  File "/home/hokenz/.local/lib/python3.10/site-packages/httpx/_client.py", line 1530, in request
    return await self.send(request, auth=auth, follow_redirects=follow_redirects)
  File "/home/hokenz/.local/lib/python3.10/site-packages/httpx/_client.py", line 1617, in send
    response = await self._send_handling_auth(
  File "/home/hokenz/.local/lib/python3.10/site-packages/httpx/_client.py", line 1645, in _send_handling_auth
    response = await self._send_handling_redirects(
  File "/home/hokenz/.local/lib/python3.10/site-packages/httpx/_client.py", line 1682, in _send_handling_redirects
    response = await self._send_single_request(request)
  File "/home/hokenz/.local/lib/python3.10/site-packages/httpx/_client.py", line 1719, in _send_single_request
    response = await transport.handle_async_request(request)
  File "/home/hokenz/.local/lib/python3.10/site-packages/httpx/_transports/default.py", line 365, in handle_async_request
    with map_httpcore_exceptions():
  File "/usr/lib/python3.10/contextlib.py", line 153, in __exit__
    self.gen.throw(typ, value, traceback)
  File "/home/hokenz/.local/lib/python3.10/site-packages/httpx/_transports/default.py", line 83, in map_httpcore_exceptions
    raise mapped_exc(message) from exc
httpx.ReadError

The above exception was the direct cause of the following exception:

Traceback (most recent call last):
  File "/home/hokenz/.local/lib/python3.10/site-packages/telegram/ext/_updater.py", line 640, in _network_loop_retry
    if not await action_cb():
  File "/home/hokenz/.local/lib/python3.10/site-packages/telegram/ext/_updater.py", line 345, in polling_action_cb
    raise exc
  File "/home/hokenz/.local/lib/python3.10/site-packages/telegram/ext/_updater.py", line 334, in polling_action_cb
    updates = await self.bot.get_updates(
  File "/home/hokenz/.local/lib/python3.10/site-packages/telegram/ext/_extbot.py", line 565, in get_updates
    updates = await super().get_updates(
  File "/home/hokenz/.local/lib/python3.10/site-packages/telegram/_bot.py", line 519, in decorator
    result = await func(self, *args, **kwargs)  # skipcq: PYL-E1102
  File "/home/hokenz/.local/lib/python3.10/site-packages/telegram/_bot.py", line 3562, in get_updates
    await self._post(
  File "/home/hokenz/.local/lib/python3.10/site-packages/telegram/_bot.py", line 607, in _post
    return await self._do_post(
  File "/home/hokenz/.local/lib/python3.10/site-packages/telegram/ext/_extbot.py", line 347, in _do_post
    return await super()._do_post(
  File "/home/hokenz/.local/lib/python3.10/site-packages/telegram/_bot.py", line 635, in _do_post
    return await request.post(
  File "/home/hokenz/.local/lib/python3.10/site-packages/telegram/request/_baserequest.py", line 168, in post
    result = await self._request_wrapper(
  File "/home/hokenz/.local/lib/python3.10/site-packages/telegram/request/_baserequest.py", line 288, in _request_wrapper
    raise exc
  File "/home/hokenz/.local/lib/python3.10/site-packages/telegram/request/_baserequest.py", line 278, in _request_wrapper
    code, payload = await self.do_request(
  File "/home/hokenz/.local/lib/python3.10/site-packages/telegram/request/_httpxrequest.py", line 243, in do_request
    raise NetworkError(f"httpx.{err.__class__.__name__}: {err}") from err
telegram.error.NetworkError: httpx.ReadError: 
Error while getting Updates: httpx.ReadError: 
No error handlers are registered, logging exception.
Traceback (most recent call last):
  File "/home/hokenz/.local/lib/python3.10/site-packages/httpcore/_exceptions.py", line 10, in map_exceptions
    yield
  File "/home/hokenz/.local/lib/python3.10/site-packages/httpcore/_backends/anyio.py", line 34, in read
    return await self._stream.receive(max_bytes=max_bytes)
  File "/home/hokenz/.local/lib/python3.10/site-packages/anyio/streams/tls.py", line 198, in receive
    data = await self._call_sslobject_method(self._ssl_object.read, max_bytes)
  File "/home/hokenz/.local/lib/python3.10/site-packages/anyio/streams/tls.py", line 140, in _call_sslobject_method
    data = await self.transport_stream.receive()
  File "/home/hokenz/.local/lib/python3.10/site-packages/anyio/_backends/_asyncio.py", line 1104, in receive
    raise self._protocol.exception from None
anyio.BrokenResourceError

The above exception was the direct cause of the following exception:

Traceback (most recent call last):
  File "/home/hokenz/.local/lib/python3.10/site-packages/httpx/_transports/default.py", line 66, in map_httpcore_exceptions
    yield
  File "/home/hokenz/.local/lib/python3.10/site-packages/httpx/_transports/default.py", line 366, in handle_async_request
    resp = await self._pool.handle_async_request(req)
  File "/home/hokenz/.local/lib/python3.10/site-packages/httpcore/_async/connection_pool.py", line 268, in handle_async_request
    raise exc
  File "/home/hokenz/.local/lib/python3.10/site-packages/httpcore/_async/connection_pool.py", line 251, in handle_async_request
    response = await connection.handle_async_request(request)
  File "/home/hokenz/.local/lib/python3.10/site-packages/httpcore/_async/connection.py", line 103, in handle_async_request
    return await self._connection.handle_async_request(request)
  File "/home/hokenz/.local/lib/python3.10/site-packages/httpcore/_async/http11.py", line 133, in handle_async_request
    raise exc
  File "/home/hokenz/.local/lib/python3.10/site-packages/httpcore/_async/http11.py", line 111, in handle_async_request
    ) = await self._receive_response_headers(**kwargs)
  File "/home/hokenz/.local/lib/python3.10/site-packages/httpcore/_async/http11.py", line 176, in _receive_response_headers
    event = await self._receive_event(timeout=timeout)
  File "/home/hokenz/.local/lib/python3.10/site-packages/httpcore/_async/http11.py", line 212, in _receive_event
    data = await self._network_stream.read(
  File "/home/hokenz/.local/lib/python3.10/site-packages/httpcore/_backends/anyio.py", line 31, in read
    with map_exceptions(exc_map):
  File "/usr/lib/python3.10/contextlib.py", line 153, in __exit__
    self.gen.throw(typ, value, traceback)
  File "/home/hokenz/.local/lib/python3.10/site-packages/httpcore/_exceptions.py", line 14, in map_exceptions
    raise to_exc(exc) from exc
httpcore.ReadError

The above exception was the direct cause of the following exception:

Traceback (most recent call last):
  File "/home/hokenz/.local/lib/python3.10/site-packages/telegram/request/_httpxrequest.py", line 219, in do_request
    res = await self._client.request(
  File "/home/hokenz/.local/lib/python3.10/site-packages/httpx/_client.py", line 1530, in request
    return await self.send(request, auth=auth, follow_redirects=follow_redirects)
  File "/home/hokenz/.local/lib/python3.10/site-packages/httpx/_client.py", line 1617, in send
    response = await self._send_handling_auth(
  File "/home/hokenz/.local/lib/python3.10/site-packages/httpx/_client.py", line 1645, in _send_handling_auth
    response = await self._send_handling_redirects(
  File "/home/hokenz/.local/lib/python3.10/site-packages/httpx/_client.py", line 1682, in _send_handling_redirects
    response = await self._send_single_request(request)
  File "/home/hokenz/.local/lib/python3.10/site-packages/httpx/_client.py", line 1719, in _send_single_request
    response = await transport.handle_async_request(request)
  File "/home/hokenz/.local/lib/python3.10/site-packages/httpx/_transports/default.py", line 365, in handle_async_request
    with map_httpcore_exceptions():
  File "/usr/lib/python3.10/contextlib.py", line 153, in __exit__
    self.gen.throw(typ, value, traceback)
  File "/home/hokenz/.local/lib/python3.10/site-packages/httpx/_transports/default.py", line 83, in map_httpcore_exceptions
    raise mapped_exc(message) from exc
httpx.ReadError

The above exception was the direct cause of the following exception:

Traceback (most recent call last):
  File "/home/hokenz/.local/lib/python3.10/site-packages/telegram/ext/_updater.py", line 640, in _network_loop_retry
    if not await action_cb():
  File "/home/hokenz/.local/lib/python3.10/site-packages/telegram/ext/_updater.py", line 345, in polling_action_cb
    raise exc
  File "/home/hokenz/.local/lib/python3.10/site-packages/telegram/ext/_updater.py", line 334, in polling_action_cb
    updates = await self.bot.get_updates(
  File "/home/hokenz/.local/lib/python3.10/site-packages/telegram/ext/_extbot.py", line 565, in get_updates
    updates = await super().get_updates(
  File "/home/hokenz/.local/lib/python3.10/site-packages/telegram/_bot.py", line 519, in decorator
    result = await func(self, *args, **kwargs)  # skipcq: PYL-E1102
  File "/home/hokenz/.local/lib/python3.10/site-packages/telegram/_bot.py", line 3562, in get_updates
    await self._post(
  File "/home/hokenz/.local/lib/python3.10/site-packages/telegram/_bot.py", line 607, in _post
    return await self._do_post(
  File "/home/hokenz/.local/lib/python3.10/site-packages/telegram/ext/_extbot.py", line 347, in _do_post
    return await super()._do_post(
  File "/home/hokenz/.local/lib/python3.10/site-packages/telegram/_bot.py", line 635, in _do_post
    return await request.post(
  File "/home/hokenz/.local/lib/python3.10/site-packages/telegram/request/_baserequest.py", line 168, in post
    result = await self._request_wrapper(
  File "/home/hokenz/.local/lib/python3.10/site-packages/telegram/request/_baserequest.py", line 288, in _request_wrapper
    raise exc
  File "/home/hokenz/.local/lib/python3.10/site-packages/telegram/request/_baserequest.py", line 278, in _request_wrapper
    code, payload = await self.do_request(
  File "/home/hokenz/.local/lib/python3.10/site-packages/telegram/request/_httpxrequest.py", line 243, in do_request
    raise NetworkError(f"httpx.{err.__class__.__name__}: {err}") from err
telegram.error.NetworkError: httpx.ReadError: 
Error while getting Updates: httpx.ReadError: 
No error handlers are registered, logging exception.
Traceback (most recent call last):
  File "/home/hokenz/.local/lib/python3.10/site-packages/httpcore/_exceptions.py", line 10, in map_exceptions
    yield
  File "/home/hokenz/.local/lib/python3.10/site-packages/httpcore/_backends/anyio.py", line 34, in read
    return await self._stream.receive(max_bytes=max_bytes)
  File "/home/hokenz/.local/lib/python3.10/site-packages/anyio/streams/tls.py", line 198, in receive
    data = await self._call_sslobject_method(self._ssl_object.read, max_bytes)
  File "/home/hokenz/.local/lib/python3.10/site-packages/anyio/streams/tls.py", line 140, in _call_sslobject_method
    data = await self.transport_stream.receive()
  File "/home/hokenz/.local/lib/python3.10/site-packages/anyio/_backends/_asyncio.py", line 1104, in receive
    raise self._protocol.exception from None
anyio.BrokenResourceError

The above exception was the direct cause of the following exception:

Traceback (most recent call last):
  File "/home/hokenz/.local/lib/python3.10/site-packages/httpx/_transports/default.py", line 66, in map_httpcore_exceptions
    yield
  File "/home/hokenz/.local/lib/python3.10/site-packages/httpx/_transports/default.py", line 366, in handle_async_request
    resp = await self._pool.handle_async_request(req)
  File "/home/hokenz/.local/lib/python3.10/site-packages/httpcore/_async/connection_pool.py", line 268, in handle_async_request
    raise exc
  File "/home/hokenz/.local/lib/python3.10/site-packages/httpcore/_async/connection_pool.py", line 251, in handle_async_request
    response = await connection.handle_async_request(request)
  File "/home/hokenz/.local/lib/python3.10/site-packages/httpcore/_async/connection.py", line 103, in handle_async_request
    return await self._connection.handle_async_request(request)
  File "/home/hokenz/.local/lib/python3.10/site-packages/httpcore/_async/http11.py", line 133, in handle_async_request
    raise exc
  File "/home/hokenz/.local/lib/python3.10/site-packages/httpcore/_async/http11.py", line 111, in handle_async_request
    ) = await self._receive_response_headers(**kwargs)
  File "/home/hokenz/.local/lib/python3.10/site-packages/httpcore/_async/http11.py", line 176, in _receive_response_headers
    event = await self._receive_event(timeout=timeout)
  File "/home/hokenz/.local/lib/python3.10/site-packages/httpcore/_async/http11.py", line 212, in _receive_event
    data = await self._network_stream.read(
  File "/home/hokenz/.local/lib/python3.10/site-packages/httpcore/_backends/anyio.py", line 31, in read
    with map_exceptions(exc_map):
  File "/usr/lib/python3.10/contextlib.py", line 153, in __exit__
    self.gen.throw(typ, value, traceback)
  File "/home/hokenz/.local/lib/python3.10/site-packages/httpcore/_exceptions.py", line 14, in map_exceptions
    raise to_exc(exc) from exc
httpcore.ReadError

The above exception was the direct cause of the following exception:

Traceback (most recent call last):
  File "/home/hokenz/.local/lib/python3.10/site-packages/telegram/request/_httpxrequest.py", line 219, in do_request
    res = await self._client.request(
  File "/home/hokenz/.local/lib/python3.10/site-packages/httpx/_client.py", line 1530, in request
    return await self.send(request, auth=auth, follow_redirects=follow_redirects)
  File "/home/hokenz/.local/lib/python3.10/site-packages/httpx/_client.py", line 1617, in send
    response = await self._send_handling_auth(
  File "/home/hokenz/.local/lib/python3.10/site-packages/httpx/_client.py", line 1645, in _send_handling_auth
    response = await self._send_handling_redirects(
  File "/home/hokenz/.local/lib/python3.10/site-packages/httpx/_client.py", line 1682, in _send_handling_redirects
    response = await self._send_single_request(request)
  File "/home/hokenz/.local/lib/python3.10/site-packages/httpx/_client.py", line 1719, in _send_single_request
    response = await transport.handle_async_request(request)
  File "/home/hokenz/.local/lib/python3.10/site-packages/httpx/_transports/default.py", line 365, in handle_async_request
    with map_httpcore_exceptions():
  File "/usr/lib/python3.10/contextlib.py", line 153, in __exit__
    self.gen.throw(typ, value, traceback)
  File "/home/hokenz/.local/lib/python3.10/site-packages/httpx/_transports/default.py", line 83, in map_httpcore_exceptions
    raise mapped_exc(message) from exc
httpx.ReadError

The above exception was the direct cause of the following exception:

Traceback (most recent call last):
  File "/home/hokenz/.local/lib/python3.10/site-packages/telegram/ext/_updater.py", line 640, in _network_loop_retry
    if not await action_cb():
  File "/home/hokenz/.local/lib/python3.10/site-packages/telegram/ext/_updater.py", line 345, in polling_action_cb
    raise exc
  File "/home/hokenz/.local/lib/python3.10/site-packages/telegram/ext/_updater.py", line 334, in polling_action_cb
    updates = await self.bot.get_updates(
  File "/home/hokenz/.local/lib/python3.10/site-packages/telegram/ext/_extbot.py", line 565, in get_updates
    updates = await super().get_updates(
  File "/home/hokenz/.local/lib/python3.10/site-packages/telegram/_bot.py", line 519, in decorator
    result = await func(self, *args, **kwargs)  # skipcq: PYL-E1102
  File "/home/hokenz/.local/lib/python3.10/site-packages/telegram/_bot.py", line 3562, in get_updates
    await self._post(
  File "/home/hokenz/.local/lib/python3.10/site-packages/telegram/_bot.py", line 607, in _post
    return await self._do_post(
  File "/home/hokenz/.local/lib/python3.10/site-packages/telegram/ext/_extbot.py", line 347, in _do_post
    return await super()._do_post(
  File "/home/hokenz/.local/lib/python3.10/site-packages/telegram/_bot.py", line 635, in _do_post
    return await request.post(
  File "/home/hokenz/.local/lib/python3.10/site-packages/telegram/request/_baserequest.py", line 168, in post
    result = await self._request_wrapper(
  File "/home/hokenz/.local/lib/python3.10/site-packages/telegram/request/_baserequest.py", line 288, in _request_wrapper
    raise exc
  File "/home/hokenz/.local/lib/python3.10/site-packages/telegram/request/_baserequest.py", line 278, in _request_wrapper
    code, payload = await self.do_request(
  File "/home/hokenz/.local/lib/python3.10/site-packages/telegram/request/_httpxrequest.py", line 243, in do_request
    raise NetworkError(f"httpx.{err.__class__.__name__}: {err}") from err
telegram.error.NetworkError: httpx.ReadError: 
Error while getting Updates: httpx.ReadError: 
No error handlers are registered, logging exception.
Traceback (most recent call last):
  File "/home/hokenz/.local/lib/python3.10/site-packages/httpcore/_exceptions.py", line 10, in map_exceptions
    yield
  File "/home/hokenz/.local/lib/python3.10/site-packages/httpcore/_backends/anyio.py", line 34, in read
    return await self._stream.receive(max_bytes=max_bytes)
  File "/home/hokenz/.local/lib/python3.10/site-packages/anyio/streams/tls.py", line 198, in receive
    data = await self._call_sslobject_method(self._ssl_object.read, max_bytes)
  File "/home/hokenz/.local/lib/python3.10/site-packages/anyio/streams/tls.py", line 140, in _call_sslobject_method
    data = await self.transport_stream.receive()
  File "/home/hokenz/.local/lib/python3.10/site-packages/anyio/_backends/_asyncio.py", line 1104, in receive
    raise self._protocol.exception from None
anyio.BrokenResourceError

The above exception was the direct cause of the following exception:

Traceback (most recent call last):
  File "/home/hokenz/.local/lib/python3.10/site-packages/httpx/_transports/default.py", line 66, in map_httpcore_exceptions
    yield
  File "/home/hokenz/.local/lib/python3.10/site-packages/httpx/_transports/default.py", line 366, in handle_async_request
    resp = await self._pool.handle_async_request(req)
  File "/home/hokenz/.local/lib/python3.10/site-packages/httpcore/_async/connection_pool.py", line 268, in handle_async_request
    raise exc
  File "/home/hokenz/.local/lib/python3.10/site-packages/httpcore/_async/connection_pool.py", line 251, in handle_async_request
    response = await connection.handle_async_request(request)
  File "/home/hokenz/.local/lib/python3.10/site-packages/httpcore/_async/connection.py", line 103, in handle_async_request
    return await self._connection.handle_async_request(request)
  File "/home/hokenz/.local/lib/python3.10/site-packages/httpcore/_async/http11.py", line 133, in handle_async_request
    raise exc
  File "/home/hokenz/.local/lib/python3.10/site-packages/httpcore/_async/http11.py", line 111, in handle_async_request
    ) = await self._receive_response_headers(**kwargs)
  File "/home/hokenz/.local/lib/python3.10/site-packages/httpcore/_async/http11.py", line 176, in _receive_response_headers
    event = await self._receive_event(timeout=timeout)
  File "/home/hokenz/.local/lib/python3.10/site-packages/httpcore/_async/http11.py", line 212, in _receive_event
    data = await self._network_stream.read(
  File "/home/hokenz/.local/lib/python3.10/site-packages/httpcore/_backends/anyio.py", line 31, in read
    with map_exceptions(exc_map):
  File "/usr/lib/python3.10/contextlib.py", line 153, in __exit__
    self.gen.throw(typ, value, traceback)
  File "/home/hokenz/.local/lib/python3.10/site-packages/httpcore/_exceptions.py", line 14, in map_exceptions
    raise to_exc(exc) from exc
httpcore.ReadError

The above exception was the direct cause of the following exception:

Traceback (most recent call last):
  File "/home/hokenz/.local/lib/python3.10/site-packages/telegram/request/_httpxrequest.py", line 219, in do_request
    res = await self._client.request(
  File "/home/hokenz/.local/lib/python3.10/site-packages/httpx/_client.py", line 1530, in request
    return await self.send(request, auth=auth, follow_redirects=follow_redirects)
  File "/home/hokenz/.local/lib/python3.10/site-packages/httpx/_client.py", line 1617, in send
    response = await self._send_handling_auth(
  File "/home/hokenz/.local/lib/python3.10/site-packages/httpx/_client.py", line 1645, in _send_handling_auth
    response = await self._send_handling_redirects(
  File "/home/hokenz/.local/lib/python3.10/site-packages/httpx/_client.py", line 1682, in _send_handling_redirects
    response = await self._send_single_request(request)
  File "/home/hokenz/.local/lib/python3.10/site-packages/httpx/_client.py", line 1719, in _send_single_request
    response = await transport.handle_async_request(request)
  File "/home/hokenz/.local/lib/python3.10/site-packages/httpx/_transports/default.py", line 365, in handle_async_request
    with map_httpcore_exceptions():
  File "/usr/lib/python3.10/contextlib.py", line 153, in __exit__
    self.gen.throw(typ, value, traceback)
  File "/home/hokenz/.local/lib/python3.10/site-packages/httpx/_transports/default.py", line 83, in map_httpcore_exceptions
    raise mapped_exc(message) from exc
httpx.ReadError

The above exception was the direct cause of the following exception:

Traceback (most recent call last):
  File "/home/hokenz/.local/lib/python3.10/site-packages/telegram/ext/_updater.py", line 640, in _network_loop_retry
    if not await action_cb():
  File "/home/hokenz/.local/lib/python3.10/site-packages/telegram/ext/_updater.py", line 345, in polling_action_cb
    raise exc
  File "/home/hokenz/.local/lib/python3.10/site-packages/telegram/ext/_updater.py", line 334, in polling_action_cb
    updates = await self.bot.get_updates(
  File "/home/hokenz/.local/lib/python3.10/site-packages/telegram/ext/_extbot.py", line 565, in get_updates
    updates = await super().get_updates(
  File "/home/hokenz/.local/lib/python3.10/site-packages/telegram/_bot.py", line 519, in decorator
    result = await func(self, *args, **kwargs)  # skipcq: PYL-E1102
  File "/home/hokenz/.local/lib/python3.10/site-packages/telegram/_bot.py", line 3562, in get_updates
    await self._post(
  File "/home/hokenz/.local/lib/python3.10/site-packages/telegram/_bot.py", line 607, in _post
    return await self._do_post(
  File "/home/hokenz/.local/lib/python3.10/site-packages/telegram/ext/_extbot.py", line 347, in _do_post
    return await super()._do_post(
  File "/home/hokenz/.local/lib/python3.10/site-packages/telegram/_bot.py", line 635, in _do_post
    return await request.post(
  File "/home/hokenz/.local/lib/python3.10/site-packages/telegram/request/_baserequest.py", line 168, in post
    result = await self._request_wrapper(
  File "/home/hokenz/.local/lib/python3.10/site-packages/telegram/request/_baserequest.py", line 288, in _request_wrapper
    raise exc
  File "/home/hokenz/.local/lib/python3.10/site-packages/telegram/request/_baserequest.py", line 278, in _request_wrapper
    code, payload = await self.do_request(
  File "/home/hokenz/.local/lib/python3.10/site-packages/telegram/request/_httpxrequest.py", line 243, in do_request
    raise NetworkError(f"httpx.{err.__class__.__name__}: {err}") from err
telegram.error.NetworkError: httpx.ReadError: 
Error while getting Updates: httpx.ReadError: 
No error handlers are registered, logging exception.
Traceback (most recent call last):
  File "/home/hokenz/.local/lib/python3.10/site-packages/httpcore/_exceptions.py", line 10, in map_exceptions
    yield
  File "/home/hokenz/.local/lib/python3.10/site-packages/httpcore/_backends/anyio.py", line 34, in read
    return await self._stream.receive(max_bytes=max_bytes)
  File "/home/hokenz/.local/lib/python3.10/site-packages/anyio/streams/tls.py", line 198, in receive
    data = await self._call_sslobject_method(self._ssl_object.read, max_bytes)
  File "/home/hokenz/.local/lib/python3.10/site-packages/anyio/streams/tls.py", line 140, in _call_sslobject_method
    data = await self.transport_stream.receive()
  File "/home/hokenz/.local/lib/python3.10/site-packages/anyio/_backends/_asyncio.py", line 1104, in receive
    raise self._protocol.exception from None
anyio.BrokenResourceError

The above exception was the direct cause of the following exception:

Traceback (most recent call last):
  File "/home/hokenz/.local/lib/python3.10/site-packages/httpx/_transports/default.py", line 66, in map_httpcore_exceptions
    yield
  File "/home/hokenz/.local/lib/python3.10/site-packages/httpx/_transports/default.py", line 366, in handle_async_request
    resp = await self._pool.handle_async_request(req)
  File "/home/hokenz/.local/lib/python3.10/site-packages/httpcore/_async/connection_pool.py", line 268, in handle_async_request
    raise exc
  File "/home/hokenz/.local/lib/python3.10/site-packages/httpcore/_async/connection_pool.py", line 251, in handle_async_request
    response = await connection.handle_async_request(request)
  File "/home/hokenz/.local/lib/python3.10/site-packages/httpcore/_async/connection.py", line 103, in handle_async_request
    return await self._connection.handle_async_request(request)
  File "/home/hokenz/.local/lib/python3.10/site-packages/httpcore/_async/http11.py", line 133, in handle_async_request
    raise exc
  File "/home/hokenz/.local/lib/python3.10/site-packages/httpcore/_async/http11.py", line 111, in handle_async_request
    ) = await self._receive_response_headers(**kwargs)
  File "/home/hokenz/.local/lib/python3.10/site-packages/httpcore/_async/http11.py", line 176, in _receive_response_headers
    event = await self._receive_event(timeout=timeout)
  File "/home/hokenz/.local/lib/python3.10/site-packages/httpcore/_async/http11.py", line 212, in _receive_event
    data = await self._network_stream.read(
  File "/home/hokenz/.local/lib/python3.10/site-packages/httpcore/_backends/anyio.py", line 31, in read
    with map_exceptions(exc_map):
  File "/usr/lib/python3.10/contextlib.py", line 153, in __exit__
    self.gen.throw(typ, value, traceback)
  File "/home/hokenz/.local/lib/python3.10/site-packages/httpcore/_exceptions.py", line 14, in map_exceptions
    raise to_exc(exc) from exc
httpcore.ReadError

The above exception was the direct cause of the following exception:

Traceback (most recent call last):
  File "/home/hokenz/.local/lib/python3.10/site-packages/telegram/request/_httpxrequest.py", line 219, in do_request
    res = await self._client.request(
  File "/home/hokenz/.local/lib/python3.10/site-packages/httpx/_client.py", line 1530, in request
    return await self.send(request, auth=auth, follow_redirects=follow_redirects)
  File "/home/hokenz/.local/lib/python3.10/site-packages/httpx/_client.py", line 1617, in send
    response = await self._send_handling_auth(
  File "/home/hokenz/.local/lib/python3.10/site-packages/httpx/_client.py", line 1645, in _send_handling_auth
    response = await self._send_handling_redirects(
  File "/home/hokenz/.local/lib/python3.10/site-packages/httpx/_client.py", line 1682, in _send_handling_redirects
    response = await self._send_single_request(request)
  File "/home/hokenz/.local/lib/python3.10/site-packages/httpx/_client.py", line 1719, in _send_single_request
    response = await transport.handle_async_request(request)
  File "/home/hokenz/.local/lib/python3.10/site-packages/httpx/_transports/default.py", line 365, in handle_async_request
    with map_httpcore_exceptions():
  File "/usr/lib/python3.10/contextlib.py", line 153, in __exit__
    self.gen.throw(typ, value, traceback)
  File "/home/hokenz/.local/lib/python3.10/site-packages/httpx/_transports/default.py", line 83, in map_httpcore_exceptions
    raise mapped_exc(message) from exc
httpx.ReadError

The above exception was the direct cause of the following exception:

Traceback (most recent call last):
  File "/home/hokenz/.local/lib/python3.10/site-packages/telegram/ext/_updater.py", line 640, in _network_loop_retry
    if not await action_cb():
  File "/home/hokenz/.local/lib/python3.10/site-packages/telegram/ext/_updater.py", line 345, in polling_action_cb
    raise exc
  File "/home/hokenz/.local/lib/python3.10/site-packages/telegram/ext/_updater.py", line 334, in polling_action_cb
    updates = await self.bot.get_updates(
  File "/home/hokenz/.local/lib/python3.10/site-packages/telegram/ext/_extbot.py", line 565, in get_updates
    updates = await super().get_updates(
  File "/home/hokenz/.local/lib/python3.10/site-packages/telegram/_bot.py", line 519, in decorator
    result = await func(self, *args, **kwargs)  # skipcq: PYL-E1102
  File "/home/hokenz/.local/lib/python3.10/site-packages/telegram/_bot.py", line 3562, in get_updates
    await self._post(
  File "/home/hokenz/.local/lib/python3.10/site-packages/telegram/_bot.py", line 607, in _post
    return await self._do_post(
  File "/home/hokenz/.local/lib/python3.10/site-packages/telegram/ext/_extbot.py", line 347, in _do_post
    return await super()._do_post(
  File "/home/hokenz/.local/lib/python3.10/site-packages/telegram/_bot.py", line 635, in _do_post
    return await request.post(
  File "/home/hokenz/.local/lib/python3.10/site-packages/telegram/request/_baserequest.py", line 168, in post
    result = await self._request_wrapper(
  File "/home/hokenz/.local/lib/python3.10/site-packages/telegram/request/_baserequest.py", line 288, in _request_wrapper
    raise exc
  File "/home/hokenz/.local/lib/python3.10/site-packages/telegram/request/_baserequest.py", line 278, in _request_wrapper
    code, payload = await self.do_request(
  File "/home/hokenz/.local/lib/python3.10/site-packages/telegram/request/_httpxrequest.py", line 243, in do_request
    raise NetworkError(f"httpx.{err.__class__.__name__}: {err}") from err
telegram.error.NetworkError: httpx.ReadError: 
Error while getting Updates: httpx.ReadError: 
No error handlers are registered, logging exception.
Traceback (most recent call last):
  File "/home/hokenz/.local/lib/python3.10/site-packages/httpcore/_exceptions.py", line 10, in map_exceptions
    yield
  File "/home/hokenz/.local/lib/python3.10/site-packages/httpcore/_backends/anyio.py", line 34, in read
    return await self._stream.receive(max_bytes=max_bytes)
  File "/home/hokenz/.local/lib/python3.10/site-packages/anyio/streams/tls.py", line 198, in receive
    data = await self._call_sslobject_method(self._ssl_object.read, max_bytes)
  File "/home/hokenz/.local/lib/python3.10/site-packages/anyio/streams/tls.py", line 140, in _call_sslobject_method
    data = await self.transport_stream.receive()
  File "/home/hokenz/.local/lib/python3.10/site-packages/anyio/_backends/_asyncio.py", line 1104, in receive
    raise self._protocol.exception from None
anyio.BrokenResourceError

The above exception was the direct cause of the following exception:

Traceback (most recent call last):
  File "/home/hokenz/.local/lib/python3.10/site-packages/httpx/_transports/default.py", line 66, in map_httpcore_exceptions
    yield
  File "/home/hokenz/.local/lib/python3.10/site-packages/httpx/_transports/default.py", line 366, in handle_async_request
    resp = await self._pool.handle_async_request(req)
  File "/home/hokenz/.local/lib/python3.10/site-packages/httpcore/_async/connection_pool.py", line 268, in handle_async_request
    raise exc
  File "/home/hokenz/.local/lib/python3.10/site-packages/httpcore/_async/connection_pool.py", line 251, in handle_async_request
    response = await connection.handle_async_request(request)
  File "/home/hokenz/.local/lib/python3.10/site-packages/httpcore/_async/connection.py", line 103, in handle_async_request
    return await self._connection.handle_async_request(request)
  File "/home/hokenz/.local/lib/python3.10/site-packages/httpcore/_async/http11.py", line 133, in handle_async_request
    raise exc
  File "/home/hokenz/.local/lib/python3.10/site-packages/httpcore/_async/http11.py", line 111, in handle_async_request
    ) = await self._receive_response_headers(**kwargs)
  File "/home/hokenz/.local/lib/python3.10/site-packages/httpcore/_async/http11.py", line 176, in _receive_response_headers
    event = await self._receive_event(timeout=timeout)
  File "/home/hokenz/.local/lib/python3.10/site-packages/httpcore/_async/http11.py", line 212, in _receive_event
    data = await self._network_stream.read(
  File "/home/hokenz/.local/lib/python3.10/site-packages/httpcore/_backends/anyio.py", line 31, in read
    with map_exceptions(exc_map):
  File "/usr/lib/python3.10/contextlib.py", line 153, in __exit__
    self.gen.throw(typ, value, traceback)
  File "/home/hokenz/.local/lib/python3.10/site-packages/httpcore/_exceptions.py", line 14, in map_exceptions
    raise to_exc(exc) from exc
httpcore.ReadError

The above exception was the direct cause of the following exception:

Traceback (most recent call last):
  File "/home/hokenz/.local/lib/python3.10/site-packages/telegram/request/_httpxrequest.py", line 219, in do_request
    res = await self._client.request(
  File "/home/hokenz/.local/lib/python3.10/site-packages/httpx/_client.py", line 1530, in request
    return await self.send(request, auth=auth, follow_redirects=follow_redirects)
  File "/home/hokenz/.local/lib/python3.10/site-packages/httpx/_client.py", line 1617, in send
    response = await self._send_handling_auth(
  File "/home/hokenz/.local/lib/python3.10/site-packages/httpx/_client.py", line 1645, in _send_handling_auth
    response = await self._send_handling_redirects(
  File "/home/hokenz/.local/lib/python3.10/site-packages/httpx/_client.py", line 1682, in _send_handling_redirects
    response = await self._send_single_request(request)
  File "/home/hokenz/.local/lib/python3.10/site-packages/httpx/_client.py", line 1719, in _send_single_request
    response = await transport.handle_async_request(request)
  File "/home/hokenz/.local/lib/python3.10/site-packages/httpx/_transports/default.py", line 365, in handle_async_request
    with map_httpcore_exceptions():
  File "/usr/lib/python3.10/contextlib.py", line 153, in __exit__
    self.gen.throw(typ, value, traceback)
  File "/home/hokenz/.local/lib/python3.10/site-packages/httpx/_transports/default.py", line 83, in map_httpcore_exceptions
    raise mapped_exc(message) from exc
httpx.ReadError

The above exception was the direct cause of the following exception:

Traceback (most recent call last):
  File "/home/hokenz/.local/lib/python3.10/site-packages/telegram/ext/_updater.py", line 640, in _network_loop_retry
    if not await action_cb():
  File "/home/hokenz/.local/lib/python3.10/site-packages/telegram/ext/_updater.py", line 345, in polling_action_cb
    raise exc
  File "/home/hokenz/.local/lib/python3.10/site-packages/telegram/ext/_updater.py", line 334, in polling_action_cb
    updates = await self.bot.get_updates(
  File "/home/hokenz/.local/lib/python3.10/site-packages/telegram/ext/_extbot.py", line 565, in get_updates
    updates = await super().get_updates(
  File "/home/hokenz/.local/lib/python3.10/site-packages/telegram/_bot.py", line 519, in decorator
    result = await func(self, *args, **kwargs)  # skipcq: PYL-E1102
  File "/home/hokenz/.local/lib/python3.10/site-packages/telegram/_bot.py", line 3562, in get_updates
    await self._post(
  File "/home/hokenz/.local/lib/python3.10/site-packages/telegram/_bot.py", line 607, in _post
    return await self._do_post(
  File "/home/hokenz/.local/lib/python3.10/site-packages/telegram/ext/_extbot.py", line 347, in _do_post
    return await super()._do_post(
  File "/home/hokenz/.local/lib/python3.10/site-packages/telegram/_bot.py", line 635, in _do_post
    return await request.post(
  File "/home/hokenz/.local/lib/python3.10/site-packages/telegram/request/_baserequest.py", line 168, in post
    result = await self._request_wrapper(
  File "/home/hokenz/.local/lib/python3.10/site-packages/telegram/request/_baserequest.py", line 288, in _request_wrapper
    raise exc
  File "/home/hokenz/.local/lib/python3.10/site-packages/telegram/request/_baserequest.py", line 278, in _request_wrapper
    code, payload = await self.do_request(
  File "/home/hokenz/.local/lib/python3.10/site-packages/telegram/request/_httpxrequest.py", line 243, in do_request
    raise NetworkError(f"httpx.{err.__class__.__name__}: {err}") from err
telegram.error.NetworkError: httpx.ReadError: 
Error while getting Updates: httpx.ReadError: 
No error handlers are registered, logging exception.
Traceback (most recent call last):
  File "/home/hokenz/.local/lib/python3.10/site-packages/httpcore/_exceptions.py", line 10, in map_exceptions
    yield
  File "/home/hokenz/.local/lib/python3.10/site-packages/httpcore/_backends/anyio.py", line 34, in read
    return await self._stream.receive(max_bytes=max_bytes)
  File "/home/hokenz/.local/lib/python3.10/site-packages/anyio/streams/tls.py", line 198, in receive
    data = await self._call_sslobject_method(self._ssl_object.read, max_bytes)
  File "/home/hokenz/.local/lib/python3.10/site-packages/anyio/streams/tls.py", line 140, in _call_sslobject_method
    data = await self.transport_stream.receive()
  File "/home/hokenz/.local/lib/python3.10/site-packages/anyio/_backends/_asyncio.py", line 1104, in receive
    raise self._protocol.exception from None
anyio.BrokenResourceError

The above exception was the direct cause of the following exception:

Traceback (most recent call last):
  File "/home/hokenz/.local/lib/python3.10/site-packages/httpx/_transports/default.py", line 66, in map_httpcore_exceptions
    yield
  File "/home/hokenz/.local/lib/python3.10/site-packages/httpx/_transports/default.py", line 366, in handle_async_request
    resp = await self._pool.handle_async_request(req)
  File "/home/hokenz/.local/lib/python3.10/site-packages/httpcore/_async/connection_pool.py", line 268, in handle_async_request
    raise exc
  File "/home/hokenz/.local/lib/python3.10/site-packages/httpcore/_async/connection_pool.py", line 251, in handle_async_request
    response = await connection.handle_async_request(request)
  File "/home/hokenz/.local/lib/python3.10/site-packages/httpcore/_async/connection.py", line 103, in handle_async_request
    return await self._connection.handle_async_request(request)
  File "/home/hokenz/.local/lib/python3.10/site-packages/httpcore/_async/http11.py", line 133, in handle_async_request
    raise exc
  File "/home/hokenz/.local/lib/python3.10/site-packages/httpcore/_async/http11.py", line 111, in handle_async_request
    ) = await self._receive_response_headers(**kwargs)
  File "/home/hokenz/.local/lib/python3.10/site-packages/httpcore/_async/http11.py", line 176, in _receive_response_headers
    event = await self._receive_event(timeout=timeout)
  File "/home/hokenz/.local/lib/python3.10/site-packages/httpcore/_async/http11.py", line 212, in _receive_event
    data = await self._network_stream.read(
  File "/home/hokenz/.local/lib/python3.10/site-packages/httpcore/_backends/anyio.py", line 31, in read
    with map_exceptions(exc_map):
  File "/usr/lib/python3.10/contextlib.py", line 153, in __exit__
    self.gen.throw(typ, value, traceback)
  File "/home/hokenz/.local/lib/python3.10/site-packages/httpcore/_exceptions.py", line 14, in map_exceptions
    raise to_exc(exc) from exc
httpcore.ReadError

The above exception was the direct cause of the following exception:

Traceback (most recent call last):
  File "/home/hokenz/.local/lib/python3.10/site-packages/telegram/request/_httpxrequest.py", line 219, in do_request
    res = await self._client.request(
  File "/home/hokenz/.local/lib/python3.10/site-packages/httpx/_client.py", line 1530, in request
    return await self.send(request, auth=auth, follow_redirects=follow_redirects)
  File "/home/hokenz/.local/lib/python3.10/site-packages/httpx/_client.py", line 1617, in send
    response = await self._send_handling_auth(
  File "/home/hokenz/.local/lib/python3.10/site-packages/httpx/_client.py", line 1645, in _send_handling_auth
    response = await self._send_handling_redirects(
  File "/home/hokenz/.local/lib/python3.10/site-packages/httpx/_client.py", line 1682, in _send_handling_redirects
    response = await self._send_single_request(request)
  File "/home/hokenz/.local/lib/python3.10/site-packages/httpx/_client.py", line 1719, in _send_single_request
    response = await transport.handle_async_request(request)
  File "/home/hokenz/.local/lib/python3.10/site-packages/httpx/_transports/default.py", line 365, in handle_async_request
    with map_httpcore_exceptions():
  File "/usr/lib/python3.10/contextlib.py", line 153, in __exit__
    self.gen.throw(typ, value, traceback)
  File "/home/hokenz/.local/lib/python3.10/site-packages/httpx/_transports/default.py", line 83, in map_httpcore_exceptions
    raise mapped_exc(message) from exc
httpx.ReadError

The above exception was the direct cause of the following exception:

Traceback (most recent call last):
  File "/home/hokenz/.local/lib/python3.10/site-packages/telegram/ext/_updater.py", line 640, in _network_loop_retry
    if not await action_cb():
  File "/home/hokenz/.local/lib/python3.10/site-packages/telegram/ext/_updater.py", line 345, in polling_action_cb
    raise exc
  File "/home/hokenz/.local/lib/python3.10/site-packages/telegram/ext/_updater.py", line 334, in polling_action_cb
    updates = await self.bot.get_updates(
  File "/home/hokenz/.local/lib/python3.10/site-packages/telegram/ext/_extbot.py", line 565, in get_updates
    updates = await super().get_updates(
  File "/home/hokenz/.local/lib/python3.10/site-packages/telegram/_bot.py", line 519, in decorator
    result = await func(self, *args, **kwargs)  # skipcq: PYL-E1102
  File "/home/hokenz/.local/lib/python3.10/site-packages/telegram/_bot.py", line 3562, in get_updates
    await self._post(
  File "/home/hokenz/.local/lib/python3.10/site-packages/telegram/_bot.py", line 607, in _post
    return await self._do_post(
  File "/home/hokenz/.local/lib/python3.10/site-packages/telegram/ext/_extbot.py", line 347, in _do_post
    return await super()._do_post(
  File "/home/hokenz/.local/lib/python3.10/site-packages/telegram/_bot.py", line 635, in _do_post
    return await request.post(
  File "/home/hokenz/.local/lib/python3.10/site-packages/telegram/request/_baserequest.py", line 168, in post
    result = await self._request_wrapper(
  File "/home/hokenz/.local/lib/python3.10/site-packages/telegram/request/_baserequest.py", line 288, in _request_wrapper
    raise exc
  File "/home/hokenz/.local/lib/python3.10/site-packages/telegram/request/_baserequest.py", line 278, in _request_wrapper
    code, payload = await self.do_request(
  File "/home/hokenz/.local/lib/python3.10/site-packages/telegram/request/_httpxrequest.py", line 243, in do_request
    raise NetworkError(f"httpx.{err.__class__.__name__}: {err}") from err
telegram.error.NetworkError: httpx.ReadError: 
Error while getting Updates: httpx.ReadError: 
No error handlers are registered, logging exception.
Traceback (most recent call last):
  File "/home/hokenz/.local/lib/python3.10/site-packages/httpcore/_exceptions.py", line 10, in map_exceptions
    yield
  File "/home/hokenz/.local/lib/python3.10/site-packages/httpcore/_backends/anyio.py", line 34, in read
    return await self._stream.receive(max_bytes=max_bytes)
  File "/home/hokenz/.local/lib/python3.10/site-packages/anyio/streams/tls.py", line 198, in receive
    data = await self._call_sslobject_method(self._ssl_object.read, max_bytes)
  File "/home/hokenz/.local/lib/python3.10/site-packages/anyio/streams/tls.py", line 140, in _call_sslobject_method
    data = await self.transport_stream.receive()
  File "/home/hokenz/.local/lib/python3.10/site-packages/anyio/_backends/_asyncio.py", line 1104, in receive
    raise self._protocol.exception from None
anyio.BrokenResourceError

The above exception was the direct cause of the following exception:

Traceback (most recent call last):
  File "/home/hokenz/.local/lib/python3.10/site-packages/httpx/_transports/default.py", line 66, in map_httpcore_exceptions
    yield
  File "/home/hokenz/.local/lib/python3.10/site-packages/httpx/_transports/default.py", line 366, in handle_async_request
    resp = await self._pool.handle_async_request(req)
  File "/home/hokenz/.local/lib/python3.10/site-packages/httpcore/_async/connection_pool.py", line 268, in handle_async_request
    raise exc
  File "/home/hokenz/.local/lib/python3.10/site-packages/httpcore/_async/connection_pool.py", line 251, in handle_async_request
    response = await connection.handle_async_request(request)
  File "/home/hokenz/.local/lib/python3.10/site-packages/httpcore/_async/connection.py", line 103, in handle_async_request
    return await self._connection.handle_async_request(request)
  File "/home/hokenz/.local/lib/python3.10/site-packages/httpcore/_async/http11.py", line 133, in handle_async_request
    raise exc
  File "/home/hokenz/.local/lib/python3.10/site-packages/httpcore/_async/http11.py", line 111, in handle_async_request
    ) = await self._receive_response_headers(**kwargs)
  File "/home/hokenz/.local/lib/python3.10/site-packages/httpcore/_async/http11.py", line 176, in _receive_response_headers
    event = await self._receive_event(timeout=timeout)
  File "/home/hokenz/.local/lib/python3.10/site-packages/httpcore/_async/http11.py", line 212, in _receive_event
    data = await self._network_stream.read(
  File "/home/hokenz/.local/lib/python3.10/site-packages/httpcore/_backends/anyio.py", line 31, in read
    with map_exceptions(exc_map):
  File "/usr/lib/python3.10/contextlib.py", line 153, in __exit__
    self.gen.throw(typ, value, traceback)
  File "/home/hokenz/.local/lib/python3.10/site-packages/httpcore/_exceptions.py", line 14, in map_exceptions
    raise to_exc(exc) from exc
httpcore.ReadError

The above exception was the direct cause of the following exception:

Traceback (most recent call last):
  File "/home/hokenz/.local/lib/python3.10/site-packages/telegram/request/_httpxrequest.py", line 219, in do_request
    res = await self._client.request(
  File "/home/hokenz/.local/lib/python3.10/site-packages/httpx/_client.py", line 1530, in request
    return await self.send(request, auth=auth, follow_redirects=follow_redirects)
  File "/home/hokenz/.local/lib/python3.10/site-packages/httpx/_client.py", line 1617, in send
    response = await self._send_handling_auth(
  File "/home/hokenz/.local/lib/python3.10/site-packages/httpx/_client.py", line 1645, in _send_handling_auth
    response = await self._send_handling_redirects(
  File "/home/hokenz/.local/lib/python3.10/site-packages/httpx/_client.py", line 1682, in _send_handling_redirects
    response = await self._send_single_request(request)
  File "/home/hokenz/.local/lib/python3.10/site-packages/httpx/_client.py", line 1719, in _send_single_request
    response = await transport.handle_async_request(request)
  File "/home/hokenz/.local/lib/python3.10/site-packages/httpx/_transports/default.py", line 365, in handle_async_request
    with map_httpcore_exceptions():
  File "/usr/lib/python3.10/contextlib.py", line 153, in __exit__
    self.gen.throw(typ, value, traceback)
  File "/home/hokenz/.local/lib/python3.10/site-packages/httpx/_transports/default.py", line 83, in map_httpcore_exceptions
    raise mapped_exc(message) from exc
httpx.ReadError

The above exception was the direct cause of the following exception:

Traceback (most recent call last):
  File "/home/hokenz/.local/lib/python3.10/site-packages/telegram/ext/_updater.py", line 640, in _network_loop_retry
    if not await action_cb():
  File "/home/hokenz/.local/lib/python3.10/site-packages/telegram/ext/_updater.py", line 345, in polling_action_cb
    raise exc
  File "/home/hokenz/.local/lib/python3.10/site-packages/telegram/ext/_updater.py", line 334, in polling_action_cb
    updates = await self.bot.get_updates(
  File "/home/hokenz/.local/lib/python3.10/site-packages/telegram/ext/_extbot.py", line 565, in get_updates
    updates = await super().get_updates(
  File "/home/hokenz/.local/lib/python3.10/site-packages/telegram/_bot.py", line 519, in decorator
    result = await func(self, *args, **kwargs)  # skipcq: PYL-E1102
  File "/home/hokenz/.local/lib/python3.10/site-packages/telegram/_bot.py", line 3562, in get_updates
    await self._post(
  File "/home/hokenz/.local/lib/python3.10/site-packages/telegram/_bot.py", line 607, in _post
    return await self._do_post(
  File "/home/hokenz/.local/lib/python3.10/site-packages/telegram/ext/_extbot.py", line 347, in _do_post
    return await super()._do_post(
  File "/home/hokenz/.local/lib/python3.10/site-packages/telegram/_bot.py", line 635, in _do_post
    return await request.post(
  File "/home/hokenz/.local/lib/python3.10/site-packages/telegram/request/_baserequest.py", line 168, in post
    result = await self._request_wrapper(
  File "/home/hokenz/.local/lib/python3.10/site-packages/telegram/request/_baserequest.py", line 288, in _request_wrapper
    raise exc
  File "/home/hokenz/.local/lib/python3.10/site-packages/telegram/request/_baserequest.py", line 278, in _request_wrapper
    code, payload = await self.do_request(
  File "/home/hokenz/.local/lib/python3.10/site-packages/telegram/request/_httpxrequest.py", line 243, in do_request
    raise NetworkError(f"httpx.{err.__class__.__name__}: {err}") from err
telegram.error.NetworkError: httpx.ReadError: 
Error while getting Updates: httpx.ReadError: 
No error handlers are registered, logging exception.
Traceback (most recent call last):
  File "/home/hokenz/.local/lib/python3.10/site-packages/httpcore/_exceptions.py", line 10, in map_exceptions
    yield
  File "/home/hokenz/.local/lib/python3.10/site-packages/httpcore/_backends/anyio.py", line 34, in read
    return await self._stream.receive(max_bytes=max_bytes)
  File "/home/hokenz/.local/lib/python3.10/site-packages/anyio/streams/tls.py", line 198, in receive
    data = await self._call_sslobject_method(self._ssl_object.read, max_bytes)
  File "/home/hokenz/.local/lib/python3.10/site-packages/anyio/streams/tls.py", line 140, in _call_sslobject_method
    data = await self.transport_stream.receive()
  File "/home/hokenz/.local/lib/python3.10/site-packages/anyio/_backends/_asyncio.py", line 1104, in receive
    raise self._protocol.exception from None
anyio.BrokenResourceError

The above exception was the direct cause of the following exception:

Traceback (most recent call last):
  File "/home/hokenz/.local/lib/python3.10/site-packages/httpx/_transports/default.py", line 66, in map_httpcore_exceptions
    yield
  File "/home/hokenz/.local/lib/python3.10/site-packages/httpx/_transports/default.py", line 366, in handle_async_request
    resp = await self._pool.handle_async_request(req)
  File "/home/hokenz/.local/lib/python3.10/site-packages/httpcore/_async/connection_pool.py", line 268, in handle_async_request
    raise exc
  File "/home/hokenz/.local/lib/python3.10/site-packages/httpcore/_async/connection_pool.py", line 251, in handle_async_request
    response = await connection.handle_async_request(request)
  File "/home/hokenz/.local/lib/python3.10/site-packages/httpcore/_async/connection.py", line 103, in handle_async_request
    return await self._connection.handle_async_request(request)
  File "/home/hokenz/.local/lib/python3.10/site-packages/httpcore/_async/http11.py", line 133, in handle_async_request
    raise exc
  File "/home/hokenz/.local/lib/python3.10/site-packages/httpcore/_async/http11.py", line 111, in handle_async_request
    ) = await self._receive_response_headers(**kwargs)
  File "/home/hokenz/.local/lib/python3.10/site-packages/httpcore/_async/http11.py", line 176, in _receive_response_headers
    event = await self._receive_event(timeout=timeout)
  File "/home/hokenz/.local/lib/python3.10/site-packages/httpcore/_async/http11.py", line 212, in _receive_event
    data = await self._network_stream.read(
  File "/home/hokenz/.local/lib/python3.10/site-packages/httpcore/_backends/anyio.py", line 31, in read
    with map_exceptions(exc_map):
  File "/usr/lib/python3.10/contextlib.py", line 153, in __exit__
    self.gen.throw(typ, value, traceback)
  File "/home/hokenz/.local/lib/python3.10/site-packages/httpcore/_exceptions.py", line 14, in map_exceptions
    raise to_exc(exc) from exc
httpcore.ReadError

The above exception was the direct cause of the following exception:

Traceback (most recent call last):
  File "/home/hokenz/.local/lib/python3.10/site-packages/telegram/request/_httpxrequest.py", line 219, in do_request
    res = await self._client.request(
  File "/home/hokenz/.local/lib/python3.10/site-packages/httpx/_client.py", line 1530, in request
    return await self.send(request, auth=auth, follow_redirects=follow_redirects)
  File "/home/hokenz/.local/lib/python3.10/site-packages/httpx/_client.py", line 1617, in send
    response = await self._send_handling_auth(
  File "/home/hokenz/.local/lib/python3.10/site-packages/httpx/_client.py", line 1645, in _send_handling_auth
    response = await self._send_handling_redirects(
  File "/home/hokenz/.local/lib/python3.10/site-packages/httpx/_client.py", line 1682, in _send_handling_redirects
    response = await self._send_single_request(request)
  File "/home/hokenz/.local/lib/python3.10/site-packages/httpx/_client.py", line 1719, in _send_single_request
    response = await transport.handle_async_request(request)
  File "/home/hokenz/.local/lib/python3.10/site-packages/httpx/_transports/default.py", line 365, in handle_async_request
    with map_httpcore_exceptions():
  File "/usr/lib/python3.10/contextlib.py", line 153, in __exit__
    self.gen.throw(typ, value, traceback)
  File "/home/hokenz/.local/lib/python3.10/site-packages/httpx/_transports/default.py", line 83, in map_httpcore_exceptions
    raise mapped_exc(message) from exc
httpx.ReadError

The above exception was the direct cause of the following exception:

Traceback (most recent call last):
  File "/home/hokenz/.local/lib/python3.10/site-packages/telegram/ext/_updater.py", line 640, in _network_loop_retry
    if not await action_cb():
  File "/home/hokenz/.local/lib/python3.10/site-packages/telegram/ext/_updater.py", line 345, in polling_action_cb
    raise exc
  File "/home/hokenz/.local/lib/python3.10/site-packages/telegram/ext/_updater.py", line 334, in polling_action_cb
    updates = await self.bot.get_updates(
  File "/home/hokenz/.local/lib/python3.10/site-packages/telegram/ext/_extbot.py", line 565, in get_updates
    updates = await super().get_updates(
  File "/home/hokenz/.local/lib/python3.10/site-packages/telegram/_bot.py", line 519, in decorator
    result = await func(self, *args, **kwargs)  # skipcq: PYL-E1102
  File "/home/hokenz/.local/lib/python3.10/site-packages/telegram/_bot.py", line 3562, in get_updates
    await self._post(
  File "/home/hokenz/.local/lib/python3.10/site-packages/telegram/_bot.py", line 607, in _post
    return await self._do_post(
  File "/home/hokenz/.local/lib/python3.10/site-packages/telegram/ext/_extbot.py", line 347, in _do_post
    return await super()._do_post(
  File "/home/hokenz/.local/lib/python3.10/site-packages/telegram/_bot.py", line 635, in _do_post
    return await request.post(
  File "/home/hokenz/.local/lib/python3.10/site-packages/telegram/request/_baserequest.py", line 168, in post
    result = await self._request_wrapper(
  File "/home/hokenz/.local/lib/python3.10/site-packages/telegram/request/_baserequest.py", line 288, in _request_wrapper
    raise exc
  File "/home/hokenz/.local/lib/python3.10/site-packages/telegram/request/_baserequest.py", line 278, in _request_wrapper
    code, payload = await self.do_request(
  File "/home/hokenz/.local/lib/python3.10/site-packages/telegram/request/_httpxrequest.py", line 243, in do_request
    raise NetworkError(f"httpx.{err.__class__.__name__}: {err}") from err
telegram.error.NetworkError: httpx.ReadError: 
Error while getting Updates: httpx.ReadError: 
No error handlers are registered, logging exception.
Traceback (most recent call last):
  File "/home/hokenz/.local/lib/python3.10/site-packages/httpcore/_exceptions.py", line 10, in map_exceptions
    yield
  File "/home/hokenz/.local/lib/python3.10/site-packages/httpcore/_backends/anyio.py", line 34, in read
    return await self._stream.receive(max_bytes=max_bytes)
  File "/home/hokenz/.local/lib/python3.10/site-packages/anyio/streams/tls.py", line 198, in receive
    data = await self._call_sslobject_method(self._ssl_object.read, max_bytes)
  File "/home/hokenz/.local/lib/python3.10/site-packages/anyio/streams/tls.py", line 140, in _call_sslobject_method
    data = await self.transport_stream.receive()
  File "/home/hokenz/.local/lib/python3.10/site-packages/anyio/_backends/_asyncio.py", line 1104, in receive
    raise self._protocol.exception from None
anyio.BrokenResourceError

The above exception was the direct cause of the following exception:

Traceback (most recent call last):
  File "/home/hokenz/.local/lib/python3.10/site-packages/httpx/_transports/default.py", line 66, in map_httpcore_exceptions
    yield
  File "/home/hokenz/.local/lib/python3.10/site-packages/httpx/_transports/default.py", line 366, in handle_async_request
    resp = await self._pool.handle_async_request(req)
  File "/home/hokenz/.local/lib/python3.10/site-packages/httpcore/_async/connection_pool.py", line 268, in handle_async_request
    raise exc
  File "/home/hokenz/.local/lib/python3.10/site-packages/httpcore/_async/connection_pool.py", line 251, in handle_async_request
    response = await connection.handle_async_request(request)
  File "/home/hokenz/.local/lib/python3.10/site-packages/httpcore/_async/connection.py", line 103, in handle_async_request
    return await self._connection.handle_async_request(request)
  File "/home/hokenz/.local/lib/python3.10/site-packages/httpcore/_async/http11.py", line 133, in handle_async_request
    raise exc
  File "/home/hokenz/.local/lib/python3.10/site-packages/httpcore/_async/http11.py", line 111, in handle_async_request
    ) = await self._receive_response_headers(**kwargs)
  File "/home/hokenz/.local/lib/python3.10/site-packages/httpcore/_async/http11.py", line 176, in _receive_response_headers
    event = await self._receive_event(timeout=timeout)
  File "/home/hokenz/.local/lib/python3.10/site-packages/httpcore/_async/http11.py", line 212, in _receive_event
    data = await self._network_stream.read(
  File "/home/hokenz/.local/lib/python3.10/site-packages/httpcore/_backends/anyio.py", line 31, in read
    with map_exceptions(exc_map):
  File "/usr/lib/python3.10/contextlib.py", line 153, in __exit__
    self.gen.throw(typ, value, traceback)
  File "/home/hokenz/.local/lib/python3.10/site-packages/httpcore/_exceptions.py", line 14, in map_exceptions
    raise to_exc(exc) from exc
httpcore.ReadError

The above exception was the direct cause of the following exception:

Traceback (most recent call last):
  File "/home/hokenz/.local/lib/python3.10/site-packages/telegram/request/_httpxrequest.py", line 219, in do_request
    res = await self._client.request(
  File "/home/hokenz/.local/lib/python3.10/site-packages/httpx/_client.py", line 1530, in request
    return await self.send(request, auth=auth, follow_redirects=follow_redirects)
  File "/home/hokenz/.local/lib/python3.10/site-packages/httpx/_client.py", line 1617, in send
    response = await self._send_handling_auth(
  File "/home/hokenz/.local/lib/python3.10/site-packages/httpx/_client.py", line 1645, in _send_handling_auth
    response = await self._send_handling_redirects(
  File "/home/hokenz/.local/lib/python3.10/site-packages/httpx/_client.py", line 1682, in _send_handling_redirects
    response = await self._send_single_request(request)
  File "/home/hokenz/.local/lib/python3.10/site-packages/httpx/_client.py", line 1719, in _send_single_request
    response = await transport.handle_async_request(request)
  File "/home/hokenz/.local/lib/python3.10/site-packages/httpx/_transports/default.py", line 365, in handle_async_request
    with map_httpcore_exceptions():
  File "/usr/lib/python3.10/contextlib.py", line 153, in __exit__
    self.gen.throw(typ, value, traceback)
  File "/home/hokenz/.local/lib/python3.10/site-packages/httpx/_transports/default.py", line 83, in map_httpcore_exceptions
    raise mapped_exc(message) from exc
httpx.ReadError

The above exception was the direct cause of the following exception:

Traceback (most recent call last):
  File "/home/hokenz/.local/lib/python3.10/site-packages/telegram/ext/_updater.py", line 640, in _network_loop_retry
    if not await action_cb():
  File "/home/hokenz/.local/lib/python3.10/site-packages/telegram/ext/_updater.py", line 345, in polling_action_cb
    raise exc
  File "/home/hokenz/.local/lib/python3.10/site-packages/telegram/ext/_updater.py", line 334, in polling_action_cb
    updates = await self.bot.get_updates(
  File "/home/hokenz/.local/lib/python3.10/site-packages/telegram/ext/_extbot.py", line 565, in get_updates
    updates = await super().get_updates(
  File "/home/hokenz/.local/lib/python3.10/site-packages/telegram/_bot.py", line 519, in decorator
    result = await func(self, *args, **kwargs)  # skipcq: PYL-E1102
  File "/home/hokenz/.local/lib/python3.10/site-packages/telegram/_bot.py", line 3562, in get_updates
    await self._post(
  File "/home/hokenz/.local/lib/python3.10/site-packages/telegram/_bot.py", line 607, in _post
    return await self._do_post(
  File "/home/hokenz/.local/lib/python3.10/site-packages/telegram/ext/_extbot.py", line 347, in _do_post
    return await super()._do_post(
  File "/home/hokenz/.local/lib/python3.10/site-packages/telegram/_bot.py", line 635, in _do_post
    return await request.post(
  File "/home/hokenz/.local/lib/python3.10/site-packages/telegram/request/_baserequest.py", line 168, in post
    result = await self._request_wrapper(
  File "/home/hokenz/.local/lib/python3.10/site-packages/telegram/request/_baserequest.py", line 288, in _request_wrapper
    raise exc
  File "/home/hokenz/.local/lib/python3.10/site-packages/telegram/request/_baserequest.py", line 278, in _request_wrapper
    code, payload = await self.do_request(
  File "/home/hokenz/.local/lib/python3.10/site-packages/telegram/request/_httpxrequest.py", line 243, in do_request
    raise NetworkError(f"httpx.{err.__class__.__name__}: {err}") from err
telegram.error.NetworkError: httpx.ReadError: 
Error while getting Updates: httpx.ReadError: 
No error handlers are registered, logging exception.
Traceback (most recent call last):
  File "/home/hokenz/.local/lib/python3.10/site-packages/httpcore/_exceptions.py", line 10, in map_exceptions
    yield
  File "/home/hokenz/.local/lib/python3.10/site-packages/httpcore/_backends/anyio.py", line 34, in read
    return await self._stream.receive(max_bytes=max_bytes)
  File "/home/hokenz/.local/lib/python3.10/site-packages/anyio/streams/tls.py", line 198, in receive
    data = await self._call_sslobject_method(self._ssl_object.read, max_bytes)
  File "/home/hokenz/.local/lib/python3.10/site-packages/anyio/streams/tls.py", line 140, in _call_sslobject_method
    data = await self.transport_stream.receive()
  File "/home/hokenz/.local/lib/python3.10/site-packages/anyio/_backends/_asyncio.py", line 1104, in receive
    raise self._protocol.exception from None
anyio.BrokenResourceError

The above exception was the direct cause of the following exception:

Traceback (most recent call last):
  File "/home/hokenz/.local/lib/python3.10/site-packages/httpx/_transports/default.py", line 66, in map_httpcore_exceptions
    yield
  File "/home/hokenz/.local/lib/python3.10/site-packages/httpx/_transports/default.py", line 366, in handle_async_request
    resp = await self._pool.handle_async_request(req)
  File "/home/hokenz/.local/lib/python3.10/site-packages/httpcore/_async/connection_pool.py", line 268, in handle_async_request
    raise exc
  File "/home/hokenz/.local/lib/python3.10/site-packages/httpcore/_async/connection_pool.py", line 251, in handle_async_request
    response = await connection.handle_async_request(request)
  File "/home/hokenz/.local/lib/python3.10/site-packages/httpcore/_async/connection.py", line 103, in handle_async_request
    return await self._connection.handle_async_request(request)
  File "/home/hokenz/.local/lib/python3.10/site-packages/httpcore/_async/http11.py", line 133, in handle_async_request
    raise exc
  File "/home/hokenz/.local/lib/python3.10/site-packages/httpcore/_async/http11.py", line 111, in handle_async_request
    ) = await self._receive_response_headers(**kwargs)
  File "/home/hokenz/.local/lib/python3.10/site-packages/httpcore/_async/http11.py", line 176, in _receive_response_headers
    event = await self._receive_event(timeout=timeout)
  File "/home/hokenz/.local/lib/python3.10/site-packages/httpcore/_async/http11.py", line 212, in _receive_event
    data = await self._network_stream.read(
  File "/home/hokenz/.local/lib/python3.10/site-packages/httpcore/_backends/anyio.py", line 31, in read
    with map_exceptions(exc_map):
  File "/usr/lib/python3.10/contextlib.py", line 153, in __exit__
    self.gen.throw(typ, value, traceback)
  File "/home/hokenz/.local/lib/python3.10/site-packages/httpcore/_exceptions.py", line 14, in map_exceptions
    raise to_exc(exc) from exc
httpcore.ReadError

The above exception was the direct cause of the following exception:

Traceback (most recent call last):
  File "/home/hokenz/.local/lib/python3.10/site-packages/telegram/request/_httpxrequest.py", line 219, in do_request
    res = await self._client.request(
  File "/home/hokenz/.local/lib/python3.10/site-packages/httpx/_client.py", line 1530, in request
    return await self.send(request, auth=auth, follow_redirects=follow_redirects)
  File "/home/hokenz/.local/lib/python3.10/site-packages/httpx/_client.py", line 1617, in send
    response = await self._send_handling_auth(
  File "/home/hokenz/.local/lib/python3.10/site-packages/httpx/_client.py", line 1645, in _send_handling_auth
    response = await self._send_handling_redirects(
  File "/home/hokenz/.local/lib/python3.10/site-packages/httpx/_client.py", line 1682, in _send_handling_redirects
    response = await self._send_single_request(request)
  File "/home/hokenz/.local/lib/python3.10/site-packages/httpx/_client.py", line 1719, in _send_single_request
    response = await transport.handle_async_request(request)
  File "/home/hokenz/.local/lib/python3.10/site-packages/httpx/_transports/default.py", line 365, in handle_async_request
    with map_httpcore_exceptions():
  File "/usr/lib/python3.10/contextlib.py", line 153, in __exit__
    self.gen.throw(typ, value, traceback)
  File "/home/hokenz/.local/lib/python3.10/site-packages/httpx/_transports/default.py", line 83, in map_httpcore_exceptions
    raise mapped_exc(message) from exc
httpx.ReadError

The above exception was the direct cause of the following exception:

Traceback (most recent call last):
  File "/home/hokenz/.local/lib/python3.10/site-packages/telegram/ext/_updater.py", line 640, in _network_loop_retry
    if not await action_cb():
  File "/home/hokenz/.local/lib/python3.10/site-packages/telegram/ext/_updater.py", line 345, in polling_action_cb
    raise exc
  File "/home/hokenz/.local/lib/python3.10/site-packages/telegram/ext/_updater.py", line 334, in polling_action_cb
    updates = await self.bot.get_updates(
  File "/home/hokenz/.local/lib/python3.10/site-packages/telegram/ext/_extbot.py", line 565, in get_updates
    updates = await super().get_updates(
  File "/home/hokenz/.local/lib/python3.10/site-packages/telegram/_bot.py", line 519, in decorator
    result = await func(self, *args, **kwargs)  # skipcq: PYL-E1102
  File "/home/hokenz/.local/lib/python3.10/site-packages/telegram/_bot.py", line 3562, in get_updates
    await self._post(
  File "/home/hokenz/.local/lib/python3.10/site-packages/telegram/_bot.py", line 607, in _post
    return await self._do_post(
  File "/home/hokenz/.local/lib/python3.10/site-packages/telegram/ext/_extbot.py", line 347, in _do_post
    return await super()._do_post(
  File "/home/hokenz/.local/lib/python3.10/site-packages/telegram/_bot.py", line 635, in _do_post
    return await request.post(
  File "/home/hokenz/.local/lib/python3.10/site-packages/telegram/request/_baserequest.py", line 168, in post
    result = await self._request_wrapper(
  File "/home/hokenz/.local/lib/python3.10/site-packages/telegram/request/_baserequest.py", line 288, in _request_wrapper
    raise exc
  File "/home/hokenz/.local/lib/python3.10/site-packages/telegram/request/_baserequest.py", line 278, in _request_wrapper
    code, payload = await self.do_request(
  File "/home/hokenz/.local/lib/python3.10/site-packages/telegram/request/_httpxrequest.py", line 243, in do_request
    raise NetworkError(f"httpx.{err.__class__.__name__}: {err}") from err
telegram.error.NetworkError: httpx.ReadError: 
